Workbook

Sheet Revenue-Cost_2024
B1: Daily Report - Balance Calculation Operation Cost
B2: Project | C2: : | D2: REVENUE vs OPERATION COST Tahun 2024
B3: Date | C3: : | D3: Januari - Desember 2024
B5: REVENUE & TAX
B6: Invoice Date | C6: # | D6: Detail/Description | F6: INVOICE VALUE | G6: Currency | H6: Currency Exchange | I6: INVOICE Number | J6: Client | K6: Receive Date | L6: AMOUNT RECEIVED | M6: PPn | N6: PPH (Pasal 23) | O6: Biaya transfer | P6: Remark
L7: IDR | M7: 0.11 | N7: 0.02 | Q7: con: inc.PPN11%
B8: 45301 | C8: 1 | D8: Revenue data procesing MTD_Tomori | F8: 150000000 | G8: IDR | H8: 1 | I8: INV015 | J8: TGE | K8: 45399 | L8: 166500000 | M8: 16500000 | N8: 3000000 | O8: 0
B9: 45302 | C9: 2 | D9: ALFA Service PDP-075 Pertamina Zona#4 | F9: 354210000 | G9: IDR | H9: 1 | I9: INV017 | J9: SI Jak | K9: 45350 | L9: 347125800 | M9: 38963100 | N9: 7084200 | O9: 0 | Q9: inc.PPN11%
B10: 45302 | C10: 3 | D10: ALFA Service PDS-01ST Pertamina Zona#4 | F10: 354210000 | G10: IDR | H10: 1 | I10: INV019 | J10: SI Jak | K10: 45425 | L10: 347125800 | M10: 38963100 | N10: 7084200 | O10: 0
B11: 45302 | C11: 4 | D11: ALFA Service JRK-254 Pertamina Zona#4 | F11: 354210000 | G11: IDR | H11: 1 | I11: INV018 | J11: SI Jak | K11: 45453 | L11: 347125800 | M11: 38963100 | N11: 7084200 | O11: 0
B12: 45446 | C12: 5 | D12: ALFA Service TLJ-58 Pertamina Zona#4 | F12: 354210000 | G12: IDR | H12: 1 | I12: INV020 | J12: SI Jak | K12: 45497 | L12: 347125800 | M12: 38963100 | N12: 7084200 | O12: 0
B13: 45447 | C13: 6 | D13: ALFA Service JRK-193 Pertamina Zona#4 | F13: 354210000 | G13: IDR | H13: 1 | I13: INV021 | J13: SI Jak | K13: 45516 | L13: 347125800 | M13: 38963100 | N13: 7084200 | O13: 0
B14: 45537 | C14: 7 | D14: ALFA Service JRK-163 Pertamina Zona#4 | F14: 354210000 | G14: IDR | H14: 1 | I14: INV022 | J14: SI Jak | K14: 45575 | L14: 347125800 | M14: 38963100 | N14: 7084200 | O14: 0 | Q14: inc.PPN11%
B15: 45539 | C15: 8 | D15: Revenue Repair Electric Assisted Stimulation Machine (no 23) | F15: 89000000 | G15: IDR | H15: 1 | I15: INV023 | J15: LBU | K15: 45553 | L15: 96920000 | M15: 9790000 | N15: 1780000 | O15: 0
B16: 45569 | C16: 9 | D16: ALFA Service TGB-033 Pertamina Cirebon | F16: 290000000 | G16: IDR | H16: 1 | I16: INV024 | J16: Elnusa | K16: 45646 | L16: 284197100 | M16: 31900000 | N16: 5800000 | O16: 2900 | Q16: inc.PPN11%
B17: 45569 | C17: 10 | D17: MFC Service TGB-033 Pertamina Cirebon | F17: 280000000 | G17: IDR | H17: 1 | I17: INV025 | J17: Elnusa | K17: 45653 | L17: 412577100 | M17: 30800000 | N17: 5600000 | O17: 2900
B18: 45569 | C18: 11 | D18: PLT Service TGB-033 Pertamina Cirebon | F18: 141000000 | G18: IDR | H18: 1 | I18: INV026 | J18: Elnusa | K18: 45653 | L18: 0 | M18: 15510000 | N18: 2820000 | O18: 0
B19: 45572 | C19: 12 | D19: ALFA Service JRK-095 Pertamina Zona#4 | F19: 354210000 | G19: IDR | H19: 1 | I19: INV027 | J19: SI Jak | K19: 45607 | L19: 347125800 | M19: 38963100 | N19: 7084200 | O19: 0
B20: 45576 | C20: 13 | D20: Revenue Project TIS (no 28 ) | F20: 819200000 | G20: IDR | H20: 1 | I20: INV028 | J20: Barikin Sakti | K20: 45579 | L20: 892928000 | M20: 90112000 | N20: 16384000 | O20: 0
B21: 45657 | C21: 14 | D21: Bunga Bank 2024 | F21: 6925425 | G21: IDR | H21: 1 | L21: 6925425 | M21: 0 | N21: 0 | O21: 0
B22: REVENUE (IDR) | F22: =SUM(F8:F21) | L22: =SUM(L8:L21) | M22: =SUM(M8:M21) | N22: =SUM(N8:N21) | O22: =SUM(O8:O21)
B24: PAJAK PENGELUARAN
B25: Date | C25: # | D25: Detail/Description | F25: Transaction Value | G25: Currency | H25: Currency Exchange | I25: PPN | K25: PPh (pasal 21) | M25: PPh (pasal 23) | O25: PPh (pasal 26)
I26: Transaction | J26: PPN | K26: Transaction | L26: PPh - 21 | M26: Transaction | N26: PPh - 23 | O26: Transaction | P26: PPh - 26
B27: 45302 | C27: 1 | D27: Tax PPN 11% (Project TGE MEPI Rimau Pembayaran Ke-2) | F27: 33836000 | G27: IDR | H27: 1 | I27: 33836000 | J27: 33836000
B28: 45351 | C28: 2 | D28: Tax PPN 11% (Project TGE MEPI Tomori) | F28: 16500000 | G28: IDR | H28: 1 | I28: 16500000 | J28: 16500000
B29: 45567 | C29: 3 | D29: Tax PPN 11% (Perbaikan Repair Electric Assisted Stimulation Machine) | F29: 9790000 | G29: IDR | H29: 1 | I29: 9790000 | J29: 9790000
B30: 45546 | C30: 4 | D30: Pinalty Telat bayar pajak PP21 Sewa tool ALFA 2023 | F30: 25439666 | G30: IDR | H30: 1 | K30: 25439666 | L30: 25439666
B31: 45546 | C31: 5 | D31: Tax PPN 11% pajak Inv-007 tahun 2023 sarulla project - Sibat | F31: 96126126 | G31: IDR | H31: 1 | I31: 96126126 | J31: 97126126
B32: 45589 | C32: 6 | D32: Penalty telat bayar pajak PPN project sarulla_INV-007_under Sibat | F32: 17716045 | G32: IDR | H32: 1
B33: 45593 | C33: 7 | D33: Pemindahbukan dari double bayar (29 des 2023) utk PPN Inv-028 | F33: 33836000 | G33: IDR | H33: 1 | I33: 33836000 | J33: 33836000
B34: 45607 | C34: 8 | D34: Kekurangan pajak PPn Inv-028 (barikikn Sakti)(1/3 nya dari PBK pajak) | F34: 56276000 | G34: IDR | H34: 1 | I34: 56276000 | J34: 56276000
B35: 45607 | C35: 9 | D35: Kekurangan pajak final PPH 23 keuntungan perusahaan tahun 2023 | F35: 1726469 | G35: IDR | H35: 1 | M35: 1726469 | N35: 1726469
B36: PENERIMAAN NEGARA (TAX) (IDR) | I36: PPN | J36: =SUM(J27:J35) | K36: PPh | L36: =SUM(L27:L35) | M36: PPh | N36: =SUM(N27:N35) | O36: PPh | P36: =SUM(P27:P35) | Q36: -
B37: PENERIMAAN NEGARA (TAX) (IDR) | I37: PPN | J37: =SUM(J27:J36) | K37: PPh | L37: =SUM(L27:L36) | M37: PPh | N37: =SUM(N27:N36) | O37: PPh | P37: =SUM(P27:P36)
B39: PENGELUARAN
B40: Date | C40: # | D40: Activity | E40: Source | F40: Jumlah | G40: Currency | H40: urrency Exchange | I40: Biaya Operasi | J40: Biaya Research (R&D) | K40: Biaya Sewa Peralatan | L40: Biaya Interpretasi Log Data | M40: Administrasi | N40: Pembelian Barang | O40: Sewa Kantor | P40: Kesehatan | Q40: Bisnis Dev | R40: asdasd | S40: makanan jepang | T40: aaaaa | U40: bbbbb | V40: asdsad | W40: dfgdfgdfgd | X40: 12312
D41: Allowance
B42: 45388 | C42: 1 | D42: THR 2024_Yufitri | E42: BCA | F42: 3000000 | G42: IDR | H42: 1 | I42: 3000000
D43: Biaya Bank
...

Sheet Laba rugi -2024
B3: PT. EXSPAN WIRELINE INDONESIA | G3: PT. EXSPAN WIRELINE INDONESIA
B4: LABA RUGI | TAHUN 2024 | G4: NERACA |TAHUN YANG BERAKHIR, 31 DESEMBER 2024 | K4: CATATAN KEAMANAN
K5: Kolom ini aman dari overwrite sistem.
D6: PT. Exspan Wireline Indonesia | I6: PT. Exspan Wireline Indonesia | K6: Diverifikasi pada: 2026-04-01 01:08
D7: (Rp) | I7: (Rp)
B8: PENDAPATAN | G8: AKTIVA
C9: PENDAPATAN LANGSUNG | D9: Rp | E9: =SUM('Revenue-Cost_2024'!L8:'Revenue-Cost_2024'!L21) | G9: AKTIVA LANCAR
C10: PENDAPATAN LAIN LAIN | D10: Rp | E10: =SUM('Revenue-Cost_2024'!L8:'Revenue-Cost_2024'!L21) | H10: KAS DAN SETARA KAS TAHUN SEBELUMNYA | I10: Rp | J10: 0
H11: KAS DAN SETARA KAS TAHUN LAPORAN | I11: Rp | J11: =E46-'Business Summary'!E13
B12: TOTALPENDAPATAN | D12: Rp | E12: =SUM(E9:E11) | H12: PIUTANG USAHA | I12: Rp | J12: 0
H13: PAJAK BAYAR DI MUKA (pph23) | I13: Rp | J13: 0
B14: BEBAN LANGSUNG | H14: BIAYA BAYAR DI MUKA | I14: Rp | J14: 0
C15: Biaya Operasi | D15: Rp | E15: ='Revenue-Cost_2024'!I720 | H15: PIUTANG LAIN LAIN | I15: Rp | J15: 0
C16: Biaya research (R & D) | D16: Rp | E16: ='Revenue-Cost_2024'!J720 | H16: TOTAL AKTIVA LANCAR | I16: Rp | J16: =SUM(J10:J15)
C17: BIAYA SEWA PERALATAN | D17: Rp | E17: ='Revenue-Cost_2024'!K720
C18: BIAYA Data Processing | D18: Rp | E18: ='Revenue-Cost_2024'!L720 | G18: ACTIVA TETAP
H20: INVENTARIS KANTOR | I20: Rp | J20: 0
B21: TOTAL BIAYA LANGSUNG | D21: Rp | E21: =SUM(E15:E20)
H22: TOTAL AKTIVA TETAP | I22: Rp | J22: =J20
B23: BEBAN TIDAK LANGSUNG | E23: ='Revenue-Cost_2024'!Q720
G24: ACTIVA LAIN LAIN | J24: 0
D25: Rp | J25: 0
H26: TOTAL AKTIVA LAIN LAIN | I26: Rp | J26: =SUM(J25:J25)
B27: TOTAL BIAYA TIDAK LANGSUNG | D27: Rp | E27: =SUM(E22:E26)
G28: TOTAL AKTIVA | I28: Rp | J28: =J26+J22+J16
B29: BIAYA ADMINISTRASI DAN UMUM
C30: BIAYA ADMINISTRASI | D30: Rp | E30: ='Revenue-Cost_2024'!M720 | G30: HUTANG DAN MODAL
C31: BIAYA PEMBELIAN Barang | D31: Rp | E31: ='Revenue-Cost_2024'!N720
C32: BIAYA SEWA KANTOR | D32: Rp | E32: ='Revenue-Cost_2024'!O720 | G32: HUTANG LANCAR
C33: BIAYA KESEHATAN | D33: Rp | E33: ='Revenue-Cost_2024'!P720 | H33: HUTANG USAHA | I33: Rp | J33: 0
H34: HUTANG GAJI | I34: Rp | J34: 0
B35: TOTAL BIAYA ADMINISTRASI DAN UMUM | D35: Rp | E35: =SUM(E30:E34) | H35: HUTANG PEMEGANG SAHAM | I35: Rp | J35: 0
H36: BIAYA YANG MASIH HARUS DI BAYAR | I36: Rp | J36: 0
B37: TOTAL BIAYA | D37: Rp | E37: =E35+E21+E27
H38: TOTAL HUTANG LANCAR | J38: =SUM(J33:J36)
B39: PENDAPATAN/BEBAN LAIN LAIN | D39: Rp
C40: PENDAPATAN LAINNYA | D40: Rp | E40: 0 | G40: MODAL
H41: MODAL SAHAM | I41: Rp | J41: 0
B42: LABA RUGI SEBELUM PAJAK | D42: Rp | E42: =E12-E37 | H42: LABA DI TAHAN | I42: Rp | J42: 0
H43: TOTAL LABA (RUGI) DITAHAN | I43: Rp | J43: =J28-J38-J41-J42
...

Sheet Business Summary
B3: PT. EXSPAN WIRELINE INDONESIA
B4: BUSINESS SUMMARY | TAHUN 2024
B6: # | C6: Items | D6: Amount
B7: 1 | C7: Revenue | D7: Rp | E7: =SUM('Revenue-Cost_2024'!L8:'Revenue-Cost_2024'!L21)
B8: 2 | C8: Revenue Diterima (Setelah Pajak) | D8: Rp | E8: =E7-SUM('Revenue-Cost_2024'!N8:'Revenue-Cost_2024'!N21)
B9: 3 | C9: Biaya | D9: Rp | E9: =SUM('Revenue-Cost_2024'!I720:Q720)
B10: 4 | C10: Profit SebelumTax | D10: Rp | E10: =E7-E9
B11: 5 | C11: PPh Badan (22%*50%) | D11: Rp | E11: =E10*22%*50%
B12: 6 | C12: PPh 23 Dipotong oleh client | D12: Rp | E12: =SUM('Revenue-Cost_2024'!N8:'Revenue-Cost_2024'!N21)
B13: 7 | C13: Kekurangan Bayar PPh Badan | D13: Rp | E13: =E11-E12
B14: 8 | C14: Profit After Tax | D14: Rp | E14: =E10-E13
B15: 9 | C15: Deviden Dibagi | D15: Rp | E15: =E14-E16
B16: 10 | C16: Profit Ditahan | D16: Rp | E16: 33763737
B18: DEVIDEN
B19: # | C19: Nama Lengkap | E19: Amount | G19: Pajak
B20: 1 | C20: Anevril Chairulsyah | D20: Rp | E20: =IF(C20="","",ROUND($E$15/COUNTA($C$20:$C$21), 0)) | G20: Pajak 10%
B21: 2 | C21: Alan Muhadjir | D21: Rp | E21: =IF(C21="","",ROUND($E$15/COUNTA($C$20:$C$21), 0)) | G21: Pajak 10%
