Workbook

Sheet Revenue-Cost_2030
B1: Daily Report - Balance Calculation Operation Cost
B2: Project | C2: : | D2: REVENUE vs OPERATION COST Tahun 2030
B3: Date | C3: : | D3: Januari - Desember 2030
B5: REVENUE & TAX
B6: Invoice Date | C6: # | D6: Detail/Description | F6: INVOICE VALUE | G6: Currency | H6: Currency Exchange | I6: INVOICE Number | J6: Client | K6: Receive Date | L6: AMOUNT RECEIVED | M6: PPn | N6: PPH (Pasal 23) | O6: Biaya transfer | P6: Remark
L7: IDR | M7: 0.11 | N7: 0.02 | Q7: con: inc.PPN11%
D8: Belum ada data revenue dan pajak
B9: REVENUE (IDR) | F9: =SUM(F8:F8) | L9: =SUM(L8:L8) | M9: =SUM(M8:M8) | N9: =SUM(N8:N8) | O9: =SUM(O8:O8)
B24: PAJAK PENGELUARAN
B25: Date | C25: # | D25: Detail/Description | F25: Transaction Value | G25: Currency | H25: Currency Exchange | I25: PPN | K25: PPh (pasal 21) | M25: PPh (pasal 23) | O25: PPh (pasal 26)
I26: Transaction | J26: PPN | K26: Transaction | L26: PPh - 21 | M26: Transaction | N26: PPh - 23 | O26: Transaction | P26: PPh - 26
D27: Belum ada data pajak | G27: IDR | H27: 1
B28: PENERIMAAN NEGARA (TAX) (IDR) | I28: PPN | J28: =SUM(J27:J27) | K28: PPh | L28: =SUM(L27:L27) | M28: PPh | N28: =SUM(N27:N27) | O28: PPh | P28: =SUM(P27:P27) | Q28: -
B37: PENERIMAAN NEGARA (TAX) (IDR) | I37: PPN | J37: =SUM(J27:J36) | K37: PPh | L37: =SUM(L27:L36) | M37: PPh | N37: =SUM(N27:N36) | O37: PPh | P37: =SUM(P27:P36)
B39: PENGELUARAN
B40: Date | C40: # | D40: Activity | E40: Source | F40: Jumlah | G40: Currency | H40: urrency Exchange | I40: Biaya Research (R&D) | J40: Biaya Sewa Peralatan | K40: Biaya Interpretasi Log Data | L40: Biaya Operasi | M40: diofavian | N40: Administrasi | O40: Pembelian Barang | P40: Sewa Kantor | Q40: Kesehatan | R40: Bisnis Dev | S40: asdasd | T40: makanan jepang | U40: aaaaa | V40: bbbbb | W40: asdsad | X40: dfgdfgdfgd | Y40: 12312
D41: keysha , nabil
B42: 47830 | C42: 1 | D42: 23434 | E42: BRI | F42: 220000 | G42: USD | H42: 10000 | M42: 220000
D43: -
B44: 47848 | C44: 2 | D44: asdasd | E44: Advance | F44: 234234 | G44: IDR | H44: 1 | S44: 234234
D45: Accommodation
B46: 47848 | C46: 3 | D46: qweqw | E46: BRI | F46: 138282273129 | G46: GBP | H46: 1123123 | L46: 138282273129
D47: Allowance
B48: 47848 | C48: 4 | D48: 87987000 | E48: BNI | F48: 98098000 | G48: IDR | H48: 1 | L48: 98098000
D49: keysha
B50: 47757 | C50: 5 | D50: sdasd | E50: Mandiri | F50: 14664 | G50: USD | H50: 1222 | M50: 14664
B51: 47848 | C51: 6 | D51: 3234234 | E51: Mandiri | F51: 234234 | G51: IDR | H51: 1 | M51: 234234
B52: 47848 | C52: 7 | D52: 23 | E52: Mandiri | F52: 13838729 | G52: EUR | H52: 1123 | M52: 13838729
D53: OPERATION COST AND OFFICE - Expenses Report
B54: Expense#1 | C54: : | D54: Gudang
D55: 123123
B56: 47848 | C56: 8 | D56: 123123 | E56: BCA | F56: 123123 | G56: IDR | H56: 1 | Y56: 123123
D57: Meal
B58: 47848 | C58: 9 | D58: werw | E58: BRI | F58: 123123 | G58: IDR | H58: 1 | L58: 123123
D59: nabil
B60: 47848 | C60: 10 | D60: reza | E60: BCA | F60: 30000 | G60: IDR | H60: 1 | M60: 30000
B61: Expense#2 | C61: : | D61: sasdas
D62: 123123
B63: 47848 | C63: 11 | D63: 123123 | E63: Advance | F63: 101 | G63: USD | H63: 101 | Y63: 101
D64: Allowance
...

Sheet Laba rugi -2030
B3: PT. EXSPAN WIRELINE INDONESIA | G3: PT. EXSPAN WIRELINE INDONESIA
B4: LABA RUGI | TAHUN 2030 | G4: NERACA |TAHUN YANG BERAKHIR, 31 DESEMBER 2030
D6: PT. Exspan Wireline Indonesia | I6: PT. Exspan Wireline Indonesia
D7: (Rp) | I7: (Rp)
B8: PENDAPATAN | G8: AKTIVA
C9: PENDAPATAN LANGSUNG | D9: Rp | E9: 0 | G9: AKTIVA LANCAR
C10: PENDAPATAN LAIN LAIN | D10: Rp | E10: 0 | H10: KAS DAN SETARA KAS TAHUN SEBELUMNYA | I10: Rp | J10: 0
H11: KAS DAN SETARA KAS TAHUN LAPORAN | I11: Rp | J11: =E50-'Business Summary'!E13
B12: TOTAL PENDAPATAN | D12: Rp | E12: =SUM(E9:E11) | H12: PIUTANG USAHA | I12: Rp | J12: 0
H13: PAJAK BAYAR DI MUKA (pph23) | I13: Rp | J13: 0
B14: BEBAN LANGSUNG | H14: BIAYA BAYAR DI MUKA | I14: Rp | J14: 0
C15: BIAYA RESEARCH (R&D) | D15: Rp | E15: ='Revenue-Cost_2030'!I94 | H15: PIUTANG LAIN LAIN | I15: Rp | J15: 0
C16: BIAYA SEWA PERALATAN | D16: Rp | E16: ='Revenue-Cost_2030'!J94 | H16: TOTAL AKTIVA LANCAR | I16: Rp | J16: =SUM(J10:J15)
C17: BIAYA INTERPRETASI LOG DATA | D17: Rp | E17: ='Revenue-Cost_2030'!K94
C18: BIAYA OPERASI | D18: Rp | E18: ='Revenue-Cost_2030'!L94 | G18: ACTIVA TETAP
C19: DIOFAVIAN | D19: Rp | E19: ='Revenue-Cost_2030'!M94
B20: TOTAL BIAYA LANGSUNG | D20: Rp | E20: =SUM(E15:E19) | H20: INVENTARIS KANTOR | I20: Rp | J20: 0
B22: BEBAN TIDAK LANGSUNG | H22: TOTAL AKTIVA TETAP | I22: Rp | J22: =J20
D23: Rp | E23: 0
B24: TOTAL BIAYA TIDAK LANGSUNG | D24: Rp | E24: =SUM(E23:E23) | G24: ACTIVA LAIN LAIN | J24: 0
J25: 0
B26: BIAYA ADMINISTRASI DAN UMUM | H26: TOTAL AKTIVA LAIN LAIN | I26: Rp | J26: =SUM(J25:J25)
C27: ADMINISTRASI | D27: Rp | E27: ='Revenue-Cost_2030'!N94
C28: PEMBELIAN BARANG | D28: Rp | E28: ='Revenue-Cost_2030'!O94 | G28: TOTAL AKTIVA | I28: Rp | J28: =J26+J22+J16
C29: SEWA KANTOR | D29: Rp | E29: ='Revenue-Cost_2030'!P94
C30: KESEHATAN | D30: Rp | E30: ='Revenue-Cost_2030'!Q94 | G30: HUTANG DAN MODAL
C31: BISNIS DEV | D31: Rp | E31: ='Revenue-Cost_2030'!R94
C32: ASDASD | D32: Rp | E32: ='Revenue-Cost_2030'!S94 | G32: HUTANG LANCAR
C33: MAKANAN JEPANG | D33: Rp | E33: ='Revenue-Cost_2030'!T94 | H33: HUTANG USAHA | I33: Rp | J33: 0
C34: AAAAA | D34: Rp | E34: ='Revenue-Cost_2030'!U94 | H34: HUTANG GAJI | I34: Rp | J34: 0
C35: BBBBB | D35: Rp | E35: ='Revenue-Cost_2030'!V94 | H35: HUTANG PEMEGANG SAHAM | I35: Rp | J35: 0
C36: ASDSAD | D36: Rp | E36: ='Revenue-Cost_2030'!W94 | H36: BIAYA YANG MASIH HARUS DI BAYAR | I36: Rp | J36: 0
C37: DFGDFGDFGD | D37: Rp | E37: ='Revenue-Cost_2030'!X94
C38: 12312 | D38: Rp | E38: ='Revenue-Cost_2030'!Y94 | H38: TOTAL HUTANG LANCAR | J38: =SUM(J33:J36)
B39: TOTAL BIAYA ADMINISTRASI DAN UMUM | D39: Rp | E39: =SUM(E27:E38)
G40: MODAL
B41: TOTAL BIAYA | D41: Rp | E41: =E20+E24+E39 | H41: MODAL SAHAM | I41: Rp | J41: 0
H42: LABA DI TAHAN | I42: Rp | J42: 0
B43: PENDAPATAN/BEBAN LAIN LAIN | H43: TOTAL LABA (RUGI) DITAHAN | I43: Rp | J43: =J28-J38-J41-J42
C44: PENDAPATAN LAIN LAIN | D44: Rp | E44: 0 | H44: TOTAL MODAL | I44: Rp | J44: =SUM(J41:J43)
...

Sheet Business Summary
B3: PT. EXSPAN WIRELINE INDONESIA
B4: BUSINESS SUMMARY | TAHUN 2030
B6: # | C6: Items | D6: Amount
B7: 1 | C7: Revenue | D7: Rp | E7: =SUM('Revenue-Cost_2030'!L8:L8)
B8: 2 | C8: Revenue Diterima (Setelah Pajak) | D8: Rp | E8: =E7-SUM('Revenue-Cost_2030'!N8:N8)
B9: 3 | C9: Biaya | D9: Rp | E9: =SUM('Revenue-Cost_2030'!I94:Y94)
B10: 4 | C10: Profit SebelumTax | D10: Rp | E10: =E7-E9
B11: 5 | C11: PPh Badan (22%*50%) | D11: Rp | E11: =E10*22%*50%
B12: 6 | C12: PPh 23 Dipotong oleh client | D12: Rp | E12: =SUM('Revenue-Cost_2030'!N8:N8)
B13: 7 | C13: Kekurangan Bayar PPh Badan | D13: Rp | E13: =E11-E12
B14: 8 | C14: Profit After Tax | D14: Rp | E14: =E10-E13
B15: 9 | C15: Deviden Dibagi | D15: Rp | E15: =E14-E16
B16: 10 | C16: Profit Ditahan | D16: Rp | E16: 0
B18: DEVIDEN
B19: # | C19: Nama Lengkap | D19: Rp | E19: Amount
