Workbook

Sheet Revenue-Cost_2030
B1: Daily Report - Balance Calculation Operation Cost
B2: Project | C2: : | D2: REVENUE vs OPERATION COST Tahun 2030
B3: Date | C3: : | D3: Januari - Desember 2030
B5: REVENUE & TAX
B6: Invoice Date | C6: # | D6: Detail/Description | F6: INVOICE VALUE | G6: Currency | H6: Currency Exchange | I6: INVOICE Number | J6: Client | K6: Receive Date | L6: AMOUNT RECEIVED | M6: PPn | N6: PPH (Pasal 23) | O6: Biaya transfer | P6: Remark
L7: IDR | M7: 0.11 | N7: 0.02 | Q7: con: inc.PPN11%
D8: Belum ada data revenue dan pajak
B9: REVENUE (IDR) | F9: =SUM(F8:F8) | L9: =SUM(L8:L8) | M9: =SUM(M8:M8) | N9: =SUM(N8:N8) | O9: =SUM(O8:O8)
B24: PAJAK PENGELUARAN
B25: Date | C25: # | D25: Detail/Description | F25: Transaction Value | G25: Currency | H25: Currency Exchange | I25: PPN | K25: PPh (pasal 21) | M25: PPh (pasal 23) | O25: PPh (pasal 26)
I26: Transaction | J26: PPN | K26: Transaction | L26: PPh - 21 | M26: Transaction | N26: PPh - 23 | O26: Transaction | P26: PPh - 26
D27: Belum ada data pajak | G27: IDR | H27: 1
B28: PENERIMAAN NEGARA (TAX) (IDR) | I28: PPN | J28: =SUM(J27:J27) | K28: PPh | L28: =SUM(L27:L27) | M28: PPh | N28: =SUM(N27:N27) | O28: PPh | P28: =SUM(P27:P27) | Q28: -
B37: PENERIMAAN NEGARA (TAX) (IDR) | I37: PPN | J37: =SUM(J27:J36) | K37: PPh | L37: =SUM(L27:L36) | M37: PPh | N37: =SUM(N27:N36) | O37: PPh | P37: =SUM(P27:P36)
B39: PENGELUARAN
B40: Date | C40: # | D40: Activity | E40: Source | F40: Jumlah | G40: Currency | H40: urrency Exchange | I40: Biaya Research (R&D) | J40: Biaya Operasi | K40: diofavian | L40: Biaya Sewa Peralatan | M40: Biaya Interpretasi Log Data | N40: Administrasi | O40: Pembelian Barang | P40: Sewa Kantor | Q40: Kesehatan | R40: Bisnis Dev | S40: asdasd | T40: makanan jepang | U40: aaaaa | V40: bbbbb | W40: asdsad | X40: dfgdfgdfgd | Y40: 12312
D41: keysha , nabil (Q1)
B42: 13-Dec-30 | C42: 1 | D42: 23434 | E42: BRI | F42: 220000 | G42: USD | H42: 10000 | I42: 220000
D43: - (J0)
B44: 31-Dec-30 | C44: 2 | D44: asdasd | E44: Advance | F44: 234234 | G44: IDR | H44: 1 | I44: 234234
D45: Allowance (A3)
B46: 31-Dec-30 | C46: 3 | D46: 87987000 | E46: BNI | F46: 98098000 | G46: IDR | H46: 1 | I46: 98098000
D47: keysha (Q1)
B48: 01-Oct-30 | C48: 4 | D48: sdasd | E48: Mandiri | F48: 14664 | G48: USD | H48: 1222 | I48: 14664
B49: 31-Dec-30 | C49: 5 | D49: 3234234 | E49: Mandiri | F49: 234234 | G49: IDR | H49: 1 | I49: 234234
D50: OPERATION COST AND OFFICE - Expenses Report
B51: Expense#1 | C51: : | D51: Gudang
D52: 123123 (P1)
B53: 31-Dec-30 | C53: 1 | D53: 123123 | E53: BCA | F53: 123123 | G53: IDR | H53: 1 | I53: 123123
D54: Meal (A4)
B55: 31-Dec-30 | C55: 2 | D55: werw | E55: BRI | F55: 123123 | G55: IDR | H55: 1 | I55: 123123
D56: nabil (Q2)
B57: 31-Dec-30 | C57: 3 | D57: reza | E57: BCA | F57: 30000 | G57: IDR | H57: 1 | I57: 30000
B58: Expense#2 | C58: : | D58: sasdas
D59: 123123 (P1)
B60: 31-Dec-30 | C60: 1 | D60: 123123 | E60: Advance | F60: 101 | G60: USD | H60: 101 | I60: 101
D61: Allowance (A3)
B62: 31-Dec-30 | C62: 2 | D62: 234234 | E62: Advance | F62: 234324324 | G62: IDR | H62: 1 | I62: 234324324
D63: Rental Tool (C1)
B64: 31-Dec-30 | C64: 3 | D64: 234 | E64: Advance | F64: 57776 | G64: USD | H64: 14444 | I64: 57776
...

Sheet Laba rugi -2030
B3: PT. EXSPAN WIRELINE INDONESIA | G3: PT. EXSPAN WIRELINE INDONESIA
B4: LABA RUGI | TAHUN 2024 | G4: NERACA |TAHUN YANG BERAKHIR, 31 DESEMBER 2024
D6: PT. Exspan Wireline Indonesia | I6: PT. Exspan Wireline Indonesia
D7: (Rp) | I7: (Rp)
B8: PENDAPATAN | G8: AKTIVA
C9: PENDAPATAN LANGSUNG | D9: Rp | E9: 0 | G9: AKTIVA LANCAR
C10: PENDAPATAN LAIN LAIN | D10: Rp | E10: 0 | H10: KAS DAN SETARA KAS TAHUN SEBELUMNYA | I10: Rp | J10: 0
H11: KAS DAN SETARA KAS TAHUN LAPORAN | I11: Rp | J11: =E46-'Business Summary'!E13
B12: TOTALPENDAPATAN | D12: Rp | E12: =SUM(E9:E11) | H12: PIUTANG USAHA | I12: Rp | J12: 0
H13: PAJAK BAYAR DI MUKA (pph23) | I13: Rp | J13: 0
B14: BEBAN LANGSUNG | H14: BIAYA BAYAR DI MUKA | I14: Rp | J14: 0
C15: Biaya Operasi | D15: Rp | E15: ='Revenue-Cost_2030'!I84 | H15: PIUTANG LAIN LAIN | I15: Rp | J15: 0
C16: Biaya research (R & D) | D16: Rp | E16: ='Revenue-Cost_2030'!J84 | H16: TOTAL AKTIVA LANCAR | I16: Rp | J16: =SUM(J10:J15)
C17: BIAYA SEWA PERALATAN | D17: Rp | E17: ='Revenue-Cost_2030'!K84
C18: BIAYA Data Processing | D18: Rp | E18: ='Revenue-Cost_2030'!L84 | G18: ACTIVA TETAP
H20: INVENTARIS KANTOR | I20: Rp | J20: 0
B21: TOTAL BIAYA LANGSUNG | D21: Rp | E21: =SUM(E15:E20)
H22: TOTAL AKTIVA TETAP | I22: Rp | J22: =J20
B23: BEBAN TIDAK LANGSUNG | E23: ='Revenue-Cost_2030'!Q84
G24: ACTIVA LAIN LAIN | J24: 0
D25: Rp | J25: 0
H26: TOTAL AKTIVA LAIN LAIN | I26: Rp | J26: =SUM(J25:J25)
B27: TOTAL BIAYA TIDAK LANGSUNG | D27: Rp | E27: =SUM(E22:E26)
G28: TOTAL AKTIVA | I28: Rp | J28: =J26+J22+J16
B29: BIAYA ADMINISTRASI DAN UMUM
C30: BIAYA ADMINISTRASI | D30: Rp | E30: ='Revenue-Cost_2030'!M84 | G30: HUTANG DAN MODAL
C31: BIAYA PEMBELIAN Barang | D31: Rp | E31: ='Revenue-Cost_2030'!N84
C32: BIAYA SEWA KANTOR | D32: Rp | E32: ='Revenue-Cost_2030'!O84 | G32: HUTANG LANCAR
C33: BIAYA KESEHATAN | D33: Rp | E33: ='Revenue-Cost_2030'!P84 | H33: HUTANG USAHA | I33: Rp | J33: 0
H34: HUTANG GAJI | I34: Rp | J34: 0
B35: TOTAL BIAYA ADMINISTRASI DAN UMUM | D35: Rp | E35: =SUM(E30:E34) | H35: HUTANG PEMEGANG SAHAM | I35: Rp | J35: 0
H36: BIAYA YANG MASIH HARUS DI BAYAR | I36: Rp | J36: 0
B37: TOTAL BIAYA | D37: Rp | E37: =E35+E21+E27
H38: TOTAL HUTANG LANCAR | J38: =SUM(J33:J36)
B39: PENDAPATAN/BEBAN LAIN LAIN | D39: Rp
C40: PENDAPATAN LAINNYA | D40: Rp | E40: 0 | G40: MODAL
H41: MODAL SAHAM | I41: Rp | J41: 0
B42: LABA RUGI SEBELUM PAJAK | D42: Rp | E42: =E12-E37 | H42: LABA DI TAHAN | I42: Rp | J42: 0
H43: TOTAL LABA (RUGI) DITAHAN | I43: Rp | J43: =J28-J38-J41-J42
B44: CORPORATE TAX (PPh 29) | D44: Rp | E44: 0 | H44: TOTAL MODAL | I44: Rp | J44: =SUM(J41:J43)
...

Sheet Business Summary
B3: PT. EXSPAN WIRELINE INDONESIA
B4: BUSINESS SUMMARY | TAHUN 2030
B6: # | C6: Items | D6: Amount
B7: 1 | C7: Revenue | D7: Rp | E7: =SUM('Revenue-Cost_2030'!L8:L8)
B8: 2 | C8: Revenue Diterima (Setelah Pajak) | D8: Rp | E8: =E7-SUM('Revenue-Cost_2030'!N8:N8)
B9: 3 | C9: Biaya | D9: Rp | E9: =SUM('Revenue-Cost_2030'!I84:Q84)
B10: 4 | C10: Profit SebelumTax | D10: Rp | E10: =E7-E9
B11: 5 | C11: PPh Badan (22%*50%) | D11: Rp | E11: =E10*22%*50%
B12: 6 | C12: PPh 23 Dipotong oleh client | D12: Rp | E12: =SUM('Revenue-Cost_2030'!N8:N8)
B13: 7 | C13: Kekurangan Bayar PPh Badan | D13: Rp | E13: =E11-E12
B14: 8 | C14: Profit After Tax | D14: Rp | E14: =E10-E13
B15: 9 | C15: Deviden Dibagi | D15: Rp | E15: =E14-E16
B16: 10 | C16: Profit Ditahan | D16: Rp | E16: 0
B18: DEVIDEN
B19: # | C19: Nama Lengkap | E19: Amount | G19: Pajak
