Workbook

Sheet Revenue-Cost_2024
B1: Daily Report - Balance Calculation Operation Cost
B2: Project | C2: : | D2: REVENUE vs OPERATION COST Tahun 2024
B3: Date | C3: : | D3: Januari - Desember 2024
B5: REVENUE & TAX
B6: Invoice Date | C6: # | D6: Detail/Description | F6: INVOICE VALUE | G6: Currency | H6: Currency Exchange | I6: INVOICE Number | J6: Client | K6: Receive Date | L6: AMOUNT RECEIVED | M6: PPn | N6: PPH (Pasal 23) | O6: Biaya transfer | P6: Remark
L7: IDR | M7: 0.11 | N7: 0.02 | Q7: con: inc.PPN11%
B8: 45302 | C8: 1 | D8: ALFA Service PDP-075 Pertamina Zona#4 | F8: 354210000 | G8: IDR | H8: 1 | I8: INV017 | J8: SI Jak | K8: 45350 | L8: 347125800 | M8: 38963100 | N8: 7084200 | O8: 0 | P8: Pemungut
B9: 45302 | C9: 2 | D9: ALFA Service PDP-075 Pertamina Zona#4 | F9: 354210000 | G9: IDR | H9: 1 | I9: INV017 | J9: SI Jak | K9: 45350 | L9: 347125800 | M9: 38963100 | N9: 7084200 | O9: 0 | P9: Pemungut
B10: 45302 | C10: 3 | D10: ALFA Service PDP-075 Pertamina Zona#4 | F10: 354210000 | G10: IDR | H10: 1 | I10: INV017 | J10: SI Jak | K10: 45350 | L10: 347125800 | M10: 38963100 | N10: 7084200 | O10: 0 | P10: Pemungut
B11: 45302 | C11: 4 | D11: ALFA Service PDP-075 Pertamina Zona#4 | F11: 354210000 | G11: IDR | H11: 1 | I11: INV017 | J11: SI Jak | K11: 45350 | L11: 347125800 | M11: 38963100 | N11: 7084200 | O11: 0 | P11: Pemungut
B12: 45302 | C12: 5 | D12: ALFA Service PDP-075 Pertamina Zona#4 | F12: 354210000 | G12: IDR | H12: 1 | I12: INV017 | J12: SI Jak | K12: 45350 | L12: 347125800 | M12: 38963100 | N12: 7084200 | O12: 0 | P12: Pemungut
B13: 45302 | C13: 6 | D13: ALFA Service PDP-075 Pertamina Zona#4 | F13: 354210000 | G13: IDR | H13: 1 | I13: INV017 | J13: SI Jak | K13: 45350 | L13: 347125800 | M13: 38963100 | N13: 7084200 | O13: 0 | P13: Pemungut
B14: 45302 | C14: 7 | D14: ALFA Service PDP-075 Pertamina Zona#4 | F14: 354210000 | G14: IDR | H14: 1 | I14: INV017 | J14: SI Jak | K14: 45350 | L14: 347125800 | M14: 38963100 | N14: 7084200 | O14: 0 | P14: Pemungut
B15: 45302 | C15: 8 | D15: ALFA Service PDP-075 Pertamina Zona#4 | F15: 354210000 | G15: IDR | H15: 1 | I15: INV017 | J15: SI Jak | K15: 45350 | L15: 347125800 | M15: 38963100 | N15: 7084200 | O15: 0 | P15: Pemungut
B16: 45302 | C16: 9 | D16: ALFA Service PDP-075 Pertamina Zona#4 | F16: 354210000 | G16: IDR | H16: 1 | I16: INV017 | J16: SI Jak | K16: 45350 | L16: 347125800 | M16: 38963100 | N16: 7084200 | O16: 0 | P16: Pemungut
B17: 45302 | C17: 10 | D17: ALFA Service PDP-075 Pertamina Zona#4 | F17: 354210000 | G17: IDR | H17: 1 | I17: INV017 | J17: SI Jak | K17: 45350 | L17: 347125800 | M17: 38963100 | N17: 7084200 | O17: 0 | P17: Pemungut
B18: 45302 | C18: 11 | D18: ALFA Service PDP-075 Pertamina Zona#4 | F18: 354210000 | G18: IDR | H18: 1 | I18: INV017 | J18: SI Jak | K18: 45350 | L18: 347125800 | M18: 38963100 | N18: 7084200 | O18: 0 | P18: Pemungut
B19: 45302 | C19: 12 | D19: ALFA Service PDP-075 Pertamina Zona#4 | F19: 354210000 | G19: IDR | H19: 1 | I19: INV017 | J19: SI Jak | K19: 45350 | L19: 347125800 | M19: 38963100 | N19: 7084200 | O19: 0 | P19: Pemungut
... B28: 45302 | C28: 21 | D28: ALFA Service PDP-075 Pertamina Zona#4 | F28: 354210000 | G28: IDR | H28: 1 | I28: INV017 | J28: SI Jak | K28: 45350 | L28: 347125800 | M28: 38963100 | N28: 7084200 | O28: 0 | P28: Pemungut
B29: 45301 | C29: 22 | D29: Revenue data procesing MTD_Tomori | F29: 150000000 | G29: IDR | H29: 1 | I29: INV015 | J29: TGE | K29: 45399 | L29: 166500000 | M29: 16500000 | N29: 3000000 | O29: 0
B30: 45301 | C30: 23 | D30: Revenue data procesing MTD_Tomori | F30: 150000000 | G30: IDR | H30: 1 | I30: INV015 | J30: TGE | K30: 45399 | L30: 166500000 | M30: 16500000 | N30: 3000000 | O30: 0
B31: 45301 | C31: 24 | D31: Revenue data procesing MTD_Tomori | F31: 150000000 | G31: IDR | H31: 1 | I31: INV015 | J31: TGE | K31: 45399 | L31: 166500000 | M31: 16500000 | N31: 3000000 | O31: 0
B32: 45301 | C32: 25 | D32: Revenue data procesing MTD_Tomori | F32: 150000000 | G32: IDR | H32: 1 | I32: INV015 | J32: TGE | K32: 45399 | L32: 166500000 | M32: 16500000 | N32: 3000000 | O32: 0
B33: 45301 | C33: 26 | D33: Revenue data procesing MTD_Tomori | F33: 150000000 | G33: IDR | H33: 1 | I33: INV015 | J33: TGE | K33: 45399 | L33: 166500000 | M33: 16500000 | N33: 3000000 | O33: 0
B34: 45301 | C34: 27 | D34: Revenue data procesing MTD_Tomori | F34: 150000000 | G34: IDR | H34: 1 | I34: INV015 | J34: TGE | K34: 45399 | L34: 166500000 | M34: 16500000 | N34: 3000000 | O34: 0
B35: 45301 | C35: 28 | D35: Revenue data procesing MTD_Tomori | F35: 150000000 | G35: IDR | H35: 1 | I35: INV015 | J35: TGE | K35: 45399 | L35: 166500000 | M35: 16500000 | N35: 3000000 | O35: 0
B36: 45301 | C36: 29 | D36: Revenue data procesing MTD_Tomori | F36: 150000000 | G36: IDR | H36: 1 | I36: INV015 | J36: TGE | K36: 45399 | L36: 166500000 | M36: 16500000 | N36: 3000000 | O36: 0
B37: 45301 | C37: 30 | D37: Revenue data procesing MTD_Tomori | F37: 150000000 | G37: IDR | H37: 1 | I37: INV015 | J37: TGE | K37: 45399 | L37: 166500000 | M37: 16500000 | N37: 3000000 | O37: 0
B38: 45301 | C38: 31 | D38: Revenue data procesing MTD_Tomori | F38: 150000000 | G38: IDR | H38: 1 | I38: INV015 | J38: TGE | K38: 45399 | L38: 166500000 | M38: 16500000 | N38: 3000000 | O38: 0
B39: 45301 | C39: 32 | D39: Revenue data procesing MTD_Tomori | F39: 150000000 | G39: IDR | H39: 1 | I39: INV015 | J39: TGE | K39: 45399 | L39: 166500000 | M39: 16500000 | N39: 3000000 | O39: 0
B40: 45301 | C40: 33 | D40: Revenue data procesing MTD_Tomori | F40: 150000000 | G40: IDR | H40: 1 | I40: INV015 | J40: TGE | K40: 45399 | L40: 166500000 | M40: 16500000 | N40: 3000000 | O40: 0
... B49: 45301 | C49: 42 | D49: Revenue data procesing MTD_Tomori | F49: 150000000 | G49: IDR | H49: 1 | I49: INV015 | J49: TGE | K49: 45399 | L49: 166500000 | M49: 16500000 | N49: 3000000 | O49: 0
B50: 45302 | C50: 43 | D50: ALFA Service PDS-01ST Pertamina Zona#4 | F50: 354210000 | G50: IDR | H50: 1 | I50: INV019 | J50: SI Jak | K50: 45425 | L50: 347125800 | M50: 38963100 | N50: 7084200 | O50: 0 | P50: Pemungut
B51: 45302 | C51: 44 | D51: ALFA Service PDS-01ST Pertamina Zona#4 | F51: 354210000 | G51: IDR | H51: 1 | I51: INV019 | J51: SI Jak | K51: 45425 | L51: 347125800 | M51: 38963100 | N51: 7084200 | O51: 0 | P51: Pemungut
B52: 45302 | C52: 45 | D52: ALFA Service PDS-01ST Pertamina Zona#4 | F52: 354210000 | G52: IDR | H52: 1 | I52: INV019 | J52: SI Jak | K52: 45425 | L52: 347125800 | M52: 38963100 | N52: 7084200 | O52: 0 | P52: Pemungut
B53: 45302 | C53: 46 | D53: ALFA Service PDS-01ST Pertamina Zona#4 | F53: 354210000 | G53: IDR | H53: 1 | I53: INV019 | J53: SI Jak | K53: 45425 | L53: 347125800 | M53: 38963100 | N53: 7084200 | O53: 0 | P53: Pemungut
B54: 45302 | C54: 47 | D54: ALFA Service PDS-01ST Pertamina Zona#4 | F54: 354210000 | G54: IDR | H54: 1 | I54: INV019 | J54: SI Jak | K54: 45425 | L54: 347125800 | M54: 38963100 | N54: 7084200 | O54: 0 | P54: Pemungut
B55: 45302 | C55: 48 | D55: ALFA Service PDS-01ST Pertamina Zona#4 | F55: 354210000 | G55: IDR | H55: 1 | I55: INV019 | J55: SI Jak | K55: 45425 | L55: 347125800 | M55: 38963100 | N55: 7084200 | O55: 0 | P55: Pemungut
B56: 45302 | C56: 49 | D56: ALFA Service PDS-01ST Pertamina Zona#4 | F56: 354210000 | G56: IDR | H56: 1 | I56: INV019 | J56: SI Jak | K56: 45425 | L56: 347125800 | M56: 38963100 | N56: 7084200 | O56: 0 | P56: Pemungut
B57: 45302 | C57: 50 | D57: ALFA Service PDS-01ST Pertamina Zona#4 | F57: 354210000 | G57: IDR | H57: 1 | I57: INV019 | J57: SI Jak | K57: 45425 | L57: 347125800 | M57: 38963100 | N57: 7084200 | O57: 0 | P57: Pemungut
...

Sheet Laba rugi -2024
B3: PT. EXSPAN WIRELINE INDONESIA | G3: PT. EXSPAN WIRELINE INDONESIA
B4: LABA RUGI | TAHUN 2024 | G4: NERACA |TAHUN YANG BERAKHIR, 31 DESEMBER 2024
D6: PT. Exspan Wireline Indonesia | I6: PT. Exspan Wireline Indonesia
D7: (Rp) | I7: (Rp)
B8: PENDAPATAN | G8: AKTIVA | H8: AKTIVA
C9: PENDAPATAN LANGSUNG | D9: Rp | E9: =SUM('Revenue-Cost_2024'!F8:F280) | G9: AKTIVA LANCAR | H9: AKTIVA LANCAR
C10: PENDAPATAN LAIN LAIN | D10: Rp | E10: =SUM('Revenue-Cost_2024'!F281:F301) | H10: KAS DAN SETARA KAS TAHUN SEBELUMNYA | I10: Rp | J10: 161401093
H11: KAS DAN SETARA KAS TAHUN LAPORAN | I11: Rp | J11: =ROUND(E41-'Business Summary'!E13, 0)
B12: TOTAL PENDAPATAN | D12: Rp | E12: =SUM(E9:E11) | H12: PIUTANG USAHA | I12: Rp | J12: 0
H13: PAJAK BAYAR DI MUKA (pph23) | I13: Rp | J13: 0
B14: BEBAN LANGSUNG | H14: BIAYA BAYAR DI MUKA | I14: Rp | J14: 0
C15: BIAYA SEWA PERALATAN | D15: Rp | E15: ='Revenue-Cost_2024'!I1015 | H15: PIUTANG LAIN LAIN | I15: Rp | J15: 0
C16: BIAYA RESEARCH (R&D) | D16: Rp | E16: ='Revenue-Cost_2024'!J1015 | H16: TOTAL AKTIVA LANCAR | I16: Rp | J16: =SUM(J10:J15)
C17: BIAYA INTERPRETASI LOG DATA | D17: Rp | E17: ='Revenue-Cost_2024'!K1015 | H17: ACTIVA TETAP
C18: BIAYA OPERASI | D18: Rp | E18: ='Revenue-Cost_2024'!L1015 | G18: ACTIVA TETAP
B19: TOTAL BIAYA LANGSUNG | D19: Rp | E19: =SUM(E15:E18)
H20: INVENTARIS KANTOR | I20: Rp | J20: 0
B21: BEBAN TIDAK LANGSUNG
C22: BISNIS DEV | D22: Rp | E22: ='Revenue-Cost_2024'!Q1015 | H22: TOTAL AKTIVA TETAP | I22: Rp | J22: =J20
B23: TOTAL BIAYA TIDAK LANGSUNG | D23: Rp | E23: =SUM(E22:E22)
G24: ACTIVA LAIN LAIN | H24: ACTIVA LAIN LAIN | J24: 0
B25: BIAYA ADMINISTRASI DAN UMUM | H25: TOTAL AKTIVA LAIN LAIN | I25: Rp | J25: 0
C26: ADMINISTRASI | D26: Rp | E26: ='Revenue-Cost_2024'!M1015 | H26: TOTAL AKTIVA LAIN LAIN | I26: Rp | J26: =SUM(J25:J25)
C27: PEMBELIAN BARANG | D27: Rp | E27: ='Revenue-Cost_2024'!N1015
C28: SEWA KANTOR | D28: Rp | E28: ='Revenue-Cost_2024'!O1015 | G28: TOTAL AKTIVA | H28: TOTAL AKTIVA | I28: Rp | J28: =J26+J22+J16
C29: KESEHATAN | D29: Rp | E29: ='Revenue-Cost_2024'!P1015
B30: TOTAL BIAYA ADMINISTRASI DAN UMUM | D30: Rp | E30: =SUM(E26:E29) | G30: HUTANG DAN MODAL | H30: HUTANG DAN MODAL
B32: TOTAL BIAYA | D32: Rp | E32: =E19+E23+E30 | G32: HUTANG LANCAR | H32: HUTANG LANCAR
H33: HUTANG USAHA | I33: Rp | J33: 0
B34: PENDAPATAN/BEBAN LAIN LAIN | H34: HUTANG GAJI | I34: Rp | J34: 0
C35: PENDAPATAN LAIN LAIN | D35: Rp | E35: 0 | H35: HUTANG PEMEGANG SAHAM | I35: Rp | J35: 0
H36: BIAYA YANG MASIH HARUS DI BAYAR | I36: Rp | J36: 0
B37: LABA RUGI SEBELUM PAJAK | D37: Rp | E37: =E12-E32
H38: TOTAL HUTANG LANCAR | I38: Rp | J38: =SUM(J33:J36)
B39: CORPORATE TAX (PPh 29) | D39: Rp | E39: 0
G40: MODAL | H40: MODAL
B41: LABA / RUGI BERSIH | D41: Rp | E41: =E37-E39 | H41: MODAL SAHAM | I41: Rp | J41: 0
H42: LABA DI TAHAN | I42: Rp | J42: 0
H43: TOTAL LABA (RUGI) DITAHAN | I43: Rp | J43: =J28-J38-J41-J42
H44: TOTAL MODAL | I44: Rp | J44: =SUM(J41:J43)
...

Sheet Business Summary
B3: PT. EXSPAN WIRELINE INDONESIA
B4: BUSINESS SUMMARY | TAHUN 2024
B6: # | C6: Items | D6: Amount
B7: 1 | C7: Revenue | D7: Rp | E7: =SUM('Revenue-Cost_2024'!F8:F301)
B8: 2 | C8: Revenue Diterima (Setelah Pajak) | D8: Rp | E8: =E7-SUM('Revenue-Cost_2024'!N8:N301)
B9: 3 | C9: Biaya | D9: Rp | E9: =SUM('Revenue-Cost_2024'!I1015:Q1015)
B10: 4 | C10: Profit SebelumTax | D10: Rp | E10: =E7-E9
B11: 5 | C11: PPh Badan (22%*50%) | D11: Rp | E11: =E10*22%*50%
B12: 6 | C12: PPh 23 Dipotong oleh client | D12: Rp | E12: =SUM('Revenue-Cost_2024'!N8:N301)
B13: 7 | C13: Kekurangan Bayar PPh Badan | D13: Rp | E13: =E11-E12
B14: 8 | C14: Profit After Tax | D14: Rp | E14: =E10-E13
B15: 9 | C15: Deviden Dibagi | D15: Rp | E15: =E14-E16
B16: 10 | C16: Profit Ditahan | D16: Rp | E16: 53207545
B18: DEVIDEN
B19: # | C19: Nama Lengkap | D19: Rp | E19: Amount
B20: 1 | C20: Anevril Chairulsyah | D20: Rp | E20: =IF(C20="","",ROUND($E$15/COUNTA($C$20:$C$21), 0)) | G20: Pajak 10%
B21: 2 | C21: Alan Muhadjir | D21: Rp | E21: =IF(C21="","",ROUND($E$15/COUNTA($C$20:$C$21), 0)) | G21: Pajak 10%
