Workbook

Sheet Revenue-Cost_2030
B1: Daily Report - Balance Calculation Operation Cost
B2: Project | C2: : | D2: REVENUE vs OPERATION COST Tahun 2030
B3: Date | C3: : | D3: Januari - Desember 2030
B5: REVENUE & TAX
B6: Invoice Date | C6: # | D6: Detail/Description | F6: INVOICE VALUE | G6: Currency | H6: Currency Exchange | I6: INVOICE Number | J6: Client | K6: Receive Date | L6: AMOUNT RECEIVED | M6: PPn | N6: PPH (Pasal 23) | O6: Biaya transfer | P6: Remark
L7: IDR | M7: 0.11 | N7: 0.02 | Q7: con: inc.PPN11%
D8: Belum ada data revenue dan pajak
B9: REVENUE (IDR) | F9: =SUM(F8:F8) | L9: =SUM(L8:L8) | M9: =SUM(M8:M8) | N9: =SUM(N8:N8) | O9: =SUM(O8:O8)
B24: PAJAK PENGELUARAN
B25: Date | C25: # | D25: Detail/Description | F25: Transaction Value | G25: Currency | H25: Currency Exchange | I25: PPN | K25: PPh (pasal 21) | M25: PPh (pasal 23) | O25: PPh (pasal 26)
I26: Transaction | J26: PPN | K26: Transaction | L26: PPh - 21 | M26: Transaction | N26: PPh - 23 | O26: Transaction | P26: PPh - 26
D27: Belum ada data pajak | G27: IDR | H27: 1
B28: PENERIMAAN NEGARA (TAX) (IDR) | I28: PPN | J28: =SUM(J27:J27) | K28: PPh | L28: =SUM(L27:L27) | M28: PPh | N28: =SUM(N27:N27) | O28: PPh | P28: =SUM(P27:P27)
B39: PENGELUARAN
B40: Date | C40: # | D40: Activity | E40: Source | F40: Jumlah | G40: Currency | H40: urrency Exchange | I40: Biaya Sewa Peralatan | J40: Biaya Research (R&D) | K40: Biaya Operasi | L40: diofavian | M40: asdasd | N40: 12312
D41: Accommodation , Transportation
B42: 47848 | C42: 1 | D42: 23432 | E42: BRI | F42: 123123 | G42: IDR | H42: 1 | K42: =$F42*$H42
D43: -
B44: 47848 | C44: 2 | D44: asdasd | E44: Advance | F44: 234234 | G44: IDR | H44: 1 | M44: =$F44*$H44
D45: 123123
B46: 47848 | C46: 3 | D46: 123123 | E46: BCA | F46: 10 | G46: USD | H46: 10000 | N46: =$F46*$H46
D47: Accommodation
B48: 47848 | C48: 4 | D48: qweqw | E48: BRI | F48: 123123 | G48: GBP | H48: 1123123 | K48: =$F48*$H48
D49: Allowance
B50: 47848 | C50: 5 | D50: 87987000 | E50: BNI | F50: 98098000 | G50: IDR | H50: 1 | K50: =$F50*$H50
D51: keysha
B52: 47830 | C52: 6 | D52: 23434 | E52: BRI | F52: 22 | G52: USD | H52: 10000 | L52: =$F52*$H52
B53: 47757 | C53: 7 | D53: sdasd | E53: Mandiri | F53: 12 | G53: USD | H53: 1222 | L53: =$F53*$H53
B54: 47848 | C54: 8 | D54: 3234234 | E54: Mandiri | F54: 234234 | G54: IDR | H54: 1 | L54: =$F54*$H54
B55: 47848 | C55: 9 | D55: 23 | E55: Mandiri | F55: 12323 | G55: EUR | H55: 1123 | L55: =$F55*$H55
D56: OPERATION COST AND OFFICE - Expenses Report
B57: Expense#1 | C57: : | D57: Gudang
D58: 123123
B59: 47848 | C59: 10 | D59: 123123 | E59: BCA | F59: 123123 | G59: IDR | H59: 1 | N59: =$F59*$H59
D60: Meal
B61: 47848 | C61: 11 | D61: werw | E61: BRI | F61: 123123 | G61: IDR | H61: 1 | K61: =$F61*$H61
D62: nabil
B63: 47848 | C63: 12 | D63: reza | E63: BCA | F63: 30000 | G63: IDR | H63: 1 | L63: =$F63*$H63
B64: Expense#2 | C64: : | D64: sasdas
D65: 123123
...

Sheet Laba rugi -2030
B3: PT. EXSPAN WIRELINE INDONESIA | G3: PT. EXSPAN WIRELINE INDONESIA
B4: LABA RUGI | TAHUN 2030 | G4: NERACA |TAHUN YANG BERAKHIR, 31 DESEMBER 2030
D6: PT. Exspan Wireline Indonesia | I6: PT. Exspan Wireline Indonesia
D7: (Rp) | I7: (Rp)
B8: PENDAPATAN | G8: AKTIVA | H8: AKTIVA
C9: PENDAPATAN LANGSUNG | D9: Rp | E9: 0 | G9: AKTIVA LANCAR | H9: AKTIVA LANCAR
C10: PENDAPATAN LAIN LAIN | D10: Rp | E10: 0 | H10: KAS DAN SETARA KAS TAHUN SEBELUMNYA | I10: Rp | J10: 0
H11: KAS DAN SETARA KAS TAHUN LAPORAN | I11: Rp | J11: =ROUND(E39-'Business Summary'!E13, 0)
B12: TOTAL PENDAPATAN | D12: Rp | E12: =SUM(E9:E11) | H12: PIUTANG USAHA | I12: Rp | J12: 0
H13: PAJAK BAYAR DI MUKA (pph23) | I13: Rp | J13: 0
B14: BEBAN LANGSUNG | H14: BIAYA BAYAR DI MUKA | I14: Rp | J14: 0
C15: BIAYA SEWA PERALATAN | D15: Rp | E15: ='Revenue-Cost_2030'!I107 | H15: PIUTANG LAIN LAIN | I15: Rp | J15: 0
C16: BIAYA RESEARCH (R&D) | D16: Rp | E16: ='Revenue-Cost_2030'!J107 | H16: TOTAL AKTIVA LANCAR | I16: Rp | J16: =SUM(J10:J15)
C17: BIAYA OPERASI | D17: Rp | E17: ='Revenue-Cost_2030'!K107 | H17: ACTIVA TETAP
C18: DIOFAVIAN | D18: Rp | E18: ='Revenue-Cost_2030'!L107 | G18: ACTIVA TETAP
B19: TOTAL BIAYA LANGSUNG | D19: Rp | E19: =SUM(E15:E18)
H20: INVENTARIS KANTOR | I20: Rp | J20: 0
B21: BEBAN TIDAK LANGSUNG
D22: Rp | E22: 0 | H22: TOTAL AKTIVA TETAP | I22: Rp | J22: =J20
B23: TOTAL BIAYA TIDAK LANGSUNG | D23: Rp | E23: =SUM(E22:E22)
G24: ACTIVA LAIN LAIN | H24: ACTIVA LAIN LAIN | J24: 0
B25: BIAYA ADMINISTRASI DAN UMUM | H25: TOTAL AKTIVA LAIN LAIN | I25: Rp | J25: 0
C26: ASDASD | D26: Rp | E26: ='Revenue-Cost_2030'!M107 | H26: TOTAL AKTIVA LAIN LAIN | I26: Rp | J26: =SUM(J25:J25)
C27: 12312 | D27: Rp | E27: ='Revenue-Cost_2030'!N107
B28: TOTAL BIAYA ADMINISTRASI DAN UMUM | D28: Rp | E28: =SUM(E26:E27) | G28: TOTAL AKTIVA | H28: TOTAL AKTIVA | I28: Rp | J28: =J26+J22+J16
B30: TOTAL BIAYA | D30: Rp | E30: =E19+E23+E28 | G30: HUTANG DAN MODAL | H30: HUTANG DAN MODAL
B32: PENDAPATAN/BEBAN LAIN LAIN | G32: HUTANG LANCAR | H32: HUTANG LANCAR
C33: PENDAPATAN LAIN LAIN | D33: Rp | E33: 0 | H33: HUTANG USAHA | I33: Rp | J33: 0
H34: HUTANG GAJI | I34: Rp | J34: 0
B35: LABA RUGI SEBELUM PAJAK | D35: Rp | E35: =E12-E30 | H35: HUTANG PEMEGANG SAHAM | I35: Rp | J35: 0
H36: BIAYA YANG MASIH HARUS DI BAYAR | I36: Rp | J36: 0
B37: CORPORATE TAX (PPh 29) | D37: Rp | E37: 0
H38: TOTAL HUTANG LANCAR | I38: Rp | J38: =SUM(J33:J36)
B39: LABA / RUGI BERSIH | D39: Rp | E39: =E35-E37
H40: MODAL
H41: MODAL SAHAM | I41: Rp | J41: 0
H42: LABA DI TAHAN | I42: Rp | J42: 0
H43: TOTAL LABA (RUGI) DITAHAN | I43: Rp | J43: =J28-J38-J41-J42
H44: TOTAL MODAL | I44: Rp | J44: =SUM(J41:J43)
H46: TOTAL HUTANG DAN MODAL | I46: Rp | J46: =J44+J38
...

Sheet Business Summary
B3: PT. EXSPAN WIRELINE INDONESIA
B4: BUSINESS SUMMARY | TAHUN 2030
B6: # | C6: Items | D6: Amount
B7: 1 | C7: Revenue | D7: Rp | E7: =SUM('Revenue-Cost_2030'!F8:F8)
B8: 2 | C8: Revenue Diterima (Setelah Pajak) | D8: Rp | E8: =E7-SUM('Revenue-Cost_2030'!N8:N8)
B9: 3 | C9: Biaya | D9: Rp | E9: =SUM('Revenue-Cost_2030'!I107:N107)
B10: 4 | C10: Profit SebelumTax | D10: Rp | E10: =E7-E9
B11: 5 | C11: PPh Badan (22%*50%) | D11: Rp | E11: =E10*22%*50%
B12: 6 | C12: PPh 23 Dipotong oleh client | D12: Rp | E12: =SUM('Revenue-Cost_2030'!N8:N8)
B13: 7 | C13: Kekurangan Bayar PPh Badan | D13: Rp | E13: =E11-E12
B14: 8 | C14: Profit After Tax | D14: Rp | E14: =E10-E13
B15: 9 | C15: Deviden Dibagi | D15: Rp | E15: =E14-E16
B16: 10 | C16: Profit Ditahan | D16: Rp | E16: 0
B18: DEVIDEN
B19: # | C19: Nama Lengkap | D19: Rp | E19: Amount
