Workbook

Sheet Revenue-Cost_2030
B1: Daily Report - Balance Calculation Operation Cost
B2: Project | C2: : | D2: REVENUE vs OPERATION COST Tahun 2030
B3: Date | C3: : | D3: Januari - Desember 2030
B5: REVENUE & TAX
B6: Invoice Date | C6: # | D6: Detail/Description | F6: INVOICE VALUE | G6: Currency | H6: Currency Exchange | I6: INVOICE Number | J6: Client | K6: Receive Date | L6: AMOUNT RECEIVED | M6: PPn | N6: PPH (Pasal 23) | O6: Biaya transfer | P6: Remark
L7: IDR | M7: 0.11 | N7: 0.02 | Q7: con: inc.PPN11%
D8: Belum ada data revenue dan pajak
B9: REVENUE (IDR) | F9: =SUM(F8:F8) | L9: =SUM(L8:L8) | M9: =SUM(M8:M8) | N9: =SUM(N8:N8) | O9: =SUM(O8:O8)
B24: PAJAK PENGELUARAN
B25: Date | C25: # | D25: Detail/Description | F25: Transaction Value | G25: Currency | H25: Currency Exchange | I25: PPN | K25: PPh (pasal 21) | M25: PPh (pasal 23) | O25: PPh (pasal 26)
I26: Transaction | J26: PPN | K26: Transaction | L26: PPh - 21 | M26: Transaction | N26: PPh - 23 | O26: Transaction | P26: PPh - 26
D27: Belum ada data pajak | G27: IDR | H27: 1
B28: PENERIMAAN NEGARA (TAX) (IDR) | I28: PPN | J28: =SUM(J27:J27) | K28: PPh | L28: =SUM(L27:L27) | M28: PPh | N28: =SUM(N27:N27) | O28: PPh | P28: =SUM(P27:P27) | Q28: -
B37: PENERIMAAN NEGARA (TAX) (IDR) | I37: PPN | J37: =SUM(J27:J36) | K37: PPh | L37: =SUM(L27:L36) | M37: PPh | N37: =SUM(N27:N36) | O37: PPh | P37: =SUM(P27:P36)
B39: PENGELUARAN
B40: Date | C40: # | D40: Activity | E40: Source | F40: Jumlah | G40: Currency | H40: urrency Exchange | I40: Biaya Operasi | J40: Biaya Research (R&D) | K40: Biaya Sewa Peralatan | L40: Biaya Interpretasi Log Data | M40: Administrasi | N40: Pembelian Barang | O40: Sewa Kantor | P40: Kesehatan | Q40: Bisnis Dev | R40: asdasd | S40: makanan jepang | T40: aaaaa | U40: bbbbb | V40: asdsad | W40: dfgdfgdfgd | X40: 12312
D41: Belum ada data single pengeluaran
D42: OPERATION COST AND OFFICE - Expenses Report
D43: Belum ada data batch pengeluaran
B44: TOTAL | I44: 0 | J44: 0 | K44: 0 | L44: 0 | M44: 0 | N44: 0 | O44: 0 | P44: 0 | Q44: 0 | R44: 0 | S44: 0 | T44: 0 | U44: 0 | V44: 0 | W44: 0 | X44: 0
B45: 45323 | C45: 5 | D45: Gaji Januari 2024 _Yufitri | E45: BCA | F45: 2500000 | G45: IDR | H45: 1 | I45: =F45
B46: 45356 | C46: 6 | D46: Gaji Februari 2024 + raple gaji Januari 2024_Yufitri | E46: BCA | F46: 3500000 | G46: IDR | H46: 1 | I46: 3500000
B47: 45364 | C47: 7 | D47: Ralika Jaya Utama | Permbuatan alat Downhole Wireless Telemetry | E47: BCA | F47: 100000000 | G47: IDR | H47: 1 | J47: =$F47*$H47
B48: 45379 | C48: 8 | D48: Gaji Maret 2024_Yufitri | E48: BCA | F48: 3000000 | G48: IDR | H48: 1 | I48: 3000000
B49: 45388 | C49: 9 | D49: THR 2024_Yufitri | E49: BCA | F49: 3000000 | G49: IDR | H49: 1 | I49: 3000000
B50: 45413 | C50: 10 | D50: Data proccesing MTD 4 well, project Tomori-Alan | E50: BCA | F50: 122625000 | G50: IDR | H50: 1 | L50: 122625000
B51: 45416 | C51: 11 | D51: Gaji April_Yufitri | E51: BCA | F51: 3000000 | G51: IDR | H51: 1 | I51: 3000000
B52: 45418 | C52: 12 | D52: Ralika Jaya Utama | Permbuatan alat Downhole Wireless Telemetry | E52: BRI | F52: 100000000 | G52: IDR | H52: 1 | J52: =$F52*$H52
B53: 45422 | C53: 13 | D53: Aro Energy | Moving slickline dari Duri (Toni Supriadi) ke Sungai lilin | E53: BCA | F53: 18000000 | G53: IDR | H53: 1 | I53: =$F53*$H53
B54: 45446 | C54: 14 | D54: ALFA Service TLJ-58 Pertamina Zona#4 - Rental Tool | E54: BCA | F54: 29640916 | G54: IDR | H54: 1 | K54: =$F54*$H54
B55: 45446 | C55: 15 | D55: PT Laka Indonesia | Wastafel for WIKA Anantara Ubud Bali | E55: BCA | F55: 300000000 | G55: IDR | H55: 1 | I55: =$F55*$H55
B56: 45446 | C56: 16 | D56: Gaji Mei_Yufitri | E56: BCA | F56: 3000000 | G56: IDR | H56: 1 | I56: 3000000
B57: 45447 | C57: 17 | D57: ALFA Service JRK-193 Pertamina Zona#4 - Rental Tool | E57: BCA | F57: 29640916 | G57: IDR | H57: 1 | K57: =$F57*$H57
B58: 45473 | C58: 18 | D58: Gaji Juni 2024_Yufitri | E58: BCA | F58: 3000000 | G58: IDR | H58: 1 | I58: 3000000
B59: 45473 | C59: 19 | D59: Downhole Sampling tool #1-1 GARINDO SARANA BARU | E59: BCA | F59: 39800000 | G59: IDR | H59: 1 | N59: 3980000
B60: 45476 | C60: 20 | D60: Kekurangan (PPN ) ke PT Garindo sarana Baru (Downhole Sampling) | E60: BCA | F60: 3582000 | G60: IDR | H60: 1 | N60: 3582000
B61: 45478 | C61: 21 | D61: Repair ESOR panel & Fabricate dummy test load, Payment#2 | E61: BRI | F61: 25000000 | G61: IDR | H61: 1 | I61: =$F61
B62: 45480 | C62: 22 | D62: PT Laka Indonesia | Wastafel for WIKA Anantara Ubud Bali | E62: BCA | F62: 25000000 | G62: IDR | H62: 1 | I62: =$F62*$H62
B63: 45483 | C63: 23 | D63: Pembelian Lisence Sonoechometer to PT Weebz Mandiri | E63: BCA | F63: 16650000 | G63: IDR | H63: 1 | Q63: =$F63*$H63
B64: 45492 | C64: 24 | D64: PT Laka Indonesia | Wastafel for WIKA Anantara Ubud Bali | E64: BCA | F64: 25000000 | G64: IDR | H64: 1 | I64: =$F64*$H64
...

Sheet Laba rugi -2030
B3: PT. EXSPAN WIRELINE INDONESIA | G3: PT. EXSPAN WIRELINE INDONESIA
B4: LABA RUGI | TAHUN 2024 | G4: NERACA |TAHUN YANG BERAKHIR, 31 DESEMBER 2024
D6: PT. Exspan Wireline Indonesia | I6: PT. Exspan Wireline Indonesia
D7: (Rp) | I7: (Rp)
B8: PENDAPATAN | G8: AKTIVA
C9: PENDAPATAN LANGSUNG | D9: Rp | E9: =SUM('Revenue-Cost_2030'!L8:'Revenue-Cost_2030'!L22) | G9: AKTIVA LANCAR
C10: PENDAPATAN LAIN LAIN | D10: Rp | E10: =SUM('Revenue-Cost_2030'!L8:'Revenue-Cost_2030'!L22) | H10: KAS DAN SETARA KAS TAHUN SEBELUMNYA | I10: Rp | J10: 0
H11: KAS DAN SETARA KAS TAHUN LAPORAN | I11: Rp | J11: =E46-'Business Summary'!E13
B12: TOTALPENDAPATAN | D12: Rp | E12: =SUM(E9:E11) | H12: PIUTANG USAHA | I12: Rp | J12: 0
H13: PAJAK BAYAR DI MUKA (pph23) | I13: Rp | J13: 0
B14: BEBAN LANGSUNG | H14: BIAYA BAYAR DI MUKA | I14: Rp | J14: 0
C15: Biaya Operasi | D15: Rp | E15: ='Revenue-Cost_2030'!I44 | H15: PIUTANG LAIN LAIN | I15: Rp | J15: 0
C16: Biaya research (R & D) | D16: Rp | E16: ='Revenue-Cost_2030'!J44 | H16: TOTAL AKTIVA LANCAR | I16: Rp | J16: =SUM(J10:J15)
C17: BIAYA SEWA PERALATAN | D17: Rp | E17: ='Revenue-Cost_2030'!K44
C18: BIAYA Data Processing | D18: Rp | E18: ='Revenue-Cost_2030'!L44 | G18: ACTIVA TETAP
H20: INVENTARIS KANTOR | I20: Rp | J20: 0
B21: TOTAL BIAYA LANGSUNG | D21: Rp | E21: =SUM(E15:E20)
H22: TOTAL AKTIVA TETAP | I22: Rp | J22: =J20
B23: BEBAN TIDAK LANGSUNG | E23: ='Revenue-Cost_2030'!Q44
G24: ACTIVA LAIN LAIN | J24: 0
D25: Rp | J25: 0
H26: TOTAL AKTIVA LAIN LAIN | I26: Rp | J26: =SUM(J25:J25)
B27: TOTAL BIAYA TIDAK LANGSUNG | D27: Rp | E27: =SUM(E22:E26)
G28: TOTAL AKTIVA | I28: Rp | J28: =J26+J22+J16
B29: BIAYA ADMINISTRASI DAN UMUM
C30: BIAYA ADMINISTRASI | D30: Rp | E30: ='Revenue-Cost_2030'!M44 | G30: HUTANG DAN MODAL
C31: BIAYA PEMBELIAN Barang | D31: Rp | E31: ='Revenue-Cost_2030'!N44
C32: BIAYA SEWA KANTOR | D32: Rp | E32: ='Revenue-Cost_2030'!O44 | G32: HUTANG LANCAR
C33: BIAYA KESEHATAN | D33: Rp | E33: ='Revenue-Cost_2030'!P44 | H33: HUTANG USAHA | I33: Rp | J33: 0
H34: HUTANG GAJI | I34: Rp | J34: 0
B35: TOTAL BIAYA ADMINISTRASI DAN UMUM | D35: Rp | E35: =SUM(E30:E34) | H35: HUTANG PEMEGANG SAHAM | I35: Rp | J35: 0
H36: BIAYA YANG MASIH HARUS DI BAYAR | I36: Rp | J36: 0
B37: TOTAL BIAYA | D37: Rp | E37: =E35+E21+E27
H38: TOTAL HUTANG LANCAR | J38: =SUM(J33:J36)
B39: PENDAPATAN/BEBAN LAIN LAIN | D39: Rp
C40: PENDAPATAN LAINNYA | D40: Rp | E40: 0 | G40: MODAL
H41: MODAL SAHAM | I41: Rp | J41: 0
B42: LABA RUGI SEBELUM PAJAK | D42: Rp | E42: =E12-E37 | H42: LABA DI TAHAN | I42: Rp | J42: 0
H43: TOTAL LABA (RUGI) DITAHAN | I43: Rp | J43: =J28-J38-J41-J42
B44: CORPORATE TAX (PPh 29) | D44: Rp | E44: 0 | H44: TOTAL MODAL | I44: Rp | J44: =SUM(J41:J43)
...

Sheet Business Summary
B3: PT. EXSPAN WIRELINE INDONESIA
B4: BUSINESS SUMMARY | TAHUN 2030
B6: # | C6: Items | D6: Amount
B7: 1 | C7: Revenue | D7: Rp | E7: =SUM('Revenue-Cost_2030'!L8:'Revenue-Cost_2030'!L22)
B8: 2 | C8: Revenue Diterima (Setelah Pajak) | D8: Rp | E8: =E7-SUM('Revenue-Cost_2030'!N8:'Revenue-Cost_2030'!N22)
B9: 3 | C9: Biaya | D9: Rp | E9: =SUM('Revenue-Cost_2030'!I44:Q44)
B10: 4 | C10: Profit SebelumTax | D10: Rp | E10: =E7-E9
B11: 5 | C11: PPh Badan (22%*50%) | D11: Rp | E11: =E10*22%*50%
B12: 6 | C12: PPh 23 Dipotong oleh client | D12: Rp | E12: =SUM('Revenue-Cost_2030'!N8:'Revenue-Cost_2030'!N22)
B13: 7 | C13: Kekurangan Bayar PPh Badan | D13: Rp | E13: =E11-E12
B14: 8 | C14: Profit After Tax | D14: Rp | E14: =E10-E13
B15: 9 | C15: Deviden Dibagi | D15: Rp | E15: =E14-E16
B16: 10 | C16: Profit Ditahan | D16: Rp | E16: 0
B18: DEVIDEN
B19: # | C19: Nama Lengkap | E19: Amount | G19: Pajak
