Workbook

Sheet Revenue-Cost_2024
B1: Daily Report - Balance Calculation Operation Cost
B2: Project | C2: : | D2: REVENUE vs OPERATION COST Tahun 2024
B3: Date | C3: : | D3: Januari - Desember 2024
B5: REVENUE & TAX
B6: Invoice Date | C6: # | D6: Detail/Description | F6: INVOICE VALUE | G6: Currency | H6: Currency Exchange | I6: INVOICE Number | J6: Client | K6: Receive Date | L6: AMOUNT RECEIVED | M6: PPn | N6: PPH (Pasal 23) | O6: Biaya transfer | P6: Remark
L7: IDR | M7: 0.11 | N7: 0.02 | Q7: con: inc.PPN11%
B8: 11-Jan-24 | C8: 1 | D8: ALFA Service PDP-075 Pertamina Zona#4 | F8: 354210000 | G8: IDR | H8: 1 | I8: INV017 | J8: SI Jak | K8: 28-Feb-24 | L8: 347125800 | M8: 38963100 | N8: 7084200 | O8: 0 | P8: Pemungut
B9: 10-Jan-24 | C9: 2 | D9: Revenue data procesing MTD_Tomori | F9: 150000000 | G9: IDR | H9: 1 | I9: INV015 | J9: TGE | K9: 17-Apr-24 | L9: 166500000 | M9: 16500000 | N9: 3000000 | O9: 0
B10: 11-Jan-24 | C10: 3 | D10: ALFA Service PDS-01ST Pertamina Zona#4 | F10: 354210000 | G10: IDR | H10: 1 | I10: INV019 | J10: SI Jak | K10: 13-May-24 | L10: 347125800 | M10: 38963100 | N10: 7084200 | O10: 0 | P10: Pemungut
B11: 11-Jan-24 | C11: 4 | D11: ALFA Service JRK-254 Pertamina Zona#4 | F11: 354210000 | G11: IDR | H11: 1 | I11: INV018 | J11: SI Jak | K11: 10-Jun-24 | L11: 347125800 | M11: 38963100 | N11: 7084200 | O11: 0 | P11: Pemungut
B12: 03-Jun-24 | C12: 5 | D12: ALFA Service TLJ-58 Pertamina Zona#4 | F12: 354210000 | G12: IDR | H12: 1 | I12: INV020 | J12: SI Jak | K12: 24-Jul-24 | L12: 347125800 | M12: 38963100 | N12: 7084200 | O12: 0 | P12: Pemungut
B13: 04-Jun-24 | C13: 6 | D13: ALFA Service JRK-193 Pertamina Zona#4 | F13: 354210000 | G13: IDR | H13: 1 | I13: INV021 | J13: SI Jak | K13: 12-Aug-24 | L13: 347125800 | M13: 38963100 | N13: 7084200 | O13: 0 | P13: Pemungut
B14: 04-Sep-24 | C14: 7 | D14: Revenue Repair Electric Assisted Stimulation Machine (no 23) | F14: 89000000 | G14: IDR | H14: 1 | I14: INV023 | J14: LBU | K14: 18-Sep-24 | L14: 96920000 | M14: 9790000 | N14: 1780000 | O14: 0
B15: 02-Sep-24 | C15: 8 | D15: ALFA Service JRK-163 Pertamina Zona#4 | F15: 354210000 | G15: IDR | H15: 1 | I15: INV022 | J15: SI Jak | K15: 10-Oct-24 | L15: 347125800 | M15: 38963100 | N15: 7084200 | O15: 0 | P15: Pemungut
B16: 11-Oct-24 | C16: 9 | D16: Revenue Project TIS (no 28 ) | F16: 819200000 | G16: IDR | H16: 1 | I16: INV028 | J16: Barikin Sakti | K16: 14-Oct-24 | L16: 892928000 | M16: 90112000 | N16: 16384000 | O16: 0
B17: 07-Oct-24 | C17: 10 | D17: ALFA Service JRK-095 Pertamina Zona#4 | F17: 354210000 | G17: IDR | H17: 1 | I17: INV027 | J17: SI Jak | K17: 11-Nov-24 | L17: 347125800 | M17: 38963100 | N17: 7084200 | O17: 0 | P17: Pemungut
B18: 04-Oct-24 | C18: 11 | D18: ALFA Service TGB-033 Pertamina Cirebon | F18: 290000000 | G18: IDR | H18: 1 | I18: INV024 | J18: Elnusa | K18: 20-Dec-24 | L18: 284197100 | M18: 31900000 | N18: 5800000 | O18: 2900 | P18: Pemungut
B19: 04-Oct-24 | C19: 12 | D19: MFC Service TGB-033 Pertamina Cirebon | F19: 280000000 | G19: IDR | H19: 1 | I19: INV025 | J19: Elnusa | K19: 27-Dec-24 | L19: 412577100 | M19: 30800000 | N19: 5600000 | O19: 2900 | P19: Pemungut
B20: 04-Oct-24 | C20: 13 | D20: PLT Service TGB-033 Pertamina Cirebon | F20: 141000000 | G20: IDR | H20: 1 | I20: INV026 | J20: Elnusa | K20: 27-Dec-24 | L20: 0 | M20: 15510000 | N20: 2820000 | O20: 0
B21: 31-Dec-24 | C21: 14 | D21: Bunga Bank 2024 | F21: 6925425 | G21: IDR | H21: 1 | L21: 6925425 | M21: 0 | N21: 0 | O21: 0
B22: REVENUE (IDR) | F22: =SUM(F8:F21) | L22: =SUM(L8:L21) | M22: =SUM(M8:M21) | N22: =SUM(N8:N21) | O22: =SUM(O8:O21)
B24: PAJAK PENGELUARAN
B25: Date | C25: # | D25: Detail/Description | F25: Transaction Value | G25: Currency | H25: Currency Exchange | I25: PPN | K25: PPh (pasal 21) | M25: PPh (pasal 23) | O25: PPh (pasal 26)
I26: Transaction | J26: PPN | K26: Transaction | L26: PPh - 21 | M26: Transaction | N26: PPh - 23 | O26: Transaction | P26: PPh - 26
B27: 11-Jan-24 | C27: 1 | D27: Tax PPN 11% (Project TGE MEPI Rimau Pembayaran Ke-2) | F27: 33836000 | G27: IDR | H27: 1 | I27: 33836000 | J27: 33836000
B28: 29-Feb-24 | C28: 2 | D28: Tax PPN 11% (Project TGE MEPI Tomori) | F28: 16500000 | G28: IDR | H28: 1 | I28: 16500000 | J28: 16500000
B29: 11-Sep-24 | C29: 3 | D29: Pinalty Telat bayar pajak PP21 Sewa tool ALFA 2023 | F29: 25439666 | G29: IDR | H29: 1 | K29: 25439666 | L29: 25439666
B30: 11-Sep-24 | C30: 4 | D30: Tax PPN 11% pajak Inv-007 tahun 2023 sarulla project - Sibat | F30: 96126126 | G30: IDR | H30: 1 | I30: 96126126 | J30: 97126126
B31: 02-Oct-24 | C31: 5 | D31: Tax PPN 11% (Perbaikan Repair Electric Assisted Stimulation Machine) | F31: 9790000 | G31: IDR | H31: 1 | I31: 9790000 | J31: 9790000
B32: 24-Oct-24 | C32: 6 | D32: Penalty telat bayar pajak PPN project sarulla_INV-007_under Sibat | F32: 17716045 | G32: IDR | H32: 1
B33: 28-Oct-24 | C33: 7 | D33: Pemindahbukan dari double bayar (29 des 2023) utk PPN Inv-028 | F33: 33836000 | G33: IDR | H33: 1 | I33: 33836000 | J33: 33836000
B34: 11-Nov-24 | C34: 8 | D34: Kekurangan pajak PPn Inv-028 (barikikn Sakti)(1/3 nya dari PBK pajak) | F34: 56276000 | G34: IDR | H34: 1 | I34: 56276000 | J34: 56276000
B35: 11-Nov-24 | C35: 9 | D35: Kekurangan pajak final PPH 23 keuntungan perusahaan tahun 2023 | F35: 1726469 | G35: IDR | H35: 1 | M35: 1726469 | N35: 1726469
B36: PENERIMAAN NEGARA (TAX) (IDR) | I36: PPN | J36: =SUM(J27:J35) | K36: PPh | L36: =SUM(L27:L35) | M36: PPh | N36: =SUM(N27:N35) | O36: PPh | P36: =SUM(P27:P35) | Q36: -
B37: PENERIMAAN NEGARA (TAX) (IDR) | I37: PPN | J37: =SUM(J27:J36) | K37: PPh | L37: =SUM(L27:L36) | M37: PPh | N37: =SUM(N27:N36) | O37: PPh | P37: =SUM(P27:P36)
B39: PENGELUARAN
B40: Date | C40: # | D40: Activity | E40: Source | F40: Jumlah | G40: Currency | H40: urrency Exchange | I40: Biaya Research (R&D) | J40: Biaya Sewa Peralatan | K40: Biaya Interpretasi Log Data | L40: Biaya Operasi | M40: diofavian | N40: Administrasi | O40: Pembelian Barang | P40: Sewa Kantor | Q40: Kesehatan | R40: Bisnis Dev | S40: asdasd | T40: makanan jepang | U40: aaaaa | V40: bbbbb | W40: asdsad | X40: dfgdfgdfgd | Y40: 12312
D41: Biaya Bank (E)
B42: 31-Dec-24 | C42: 1 | D42: Total Biaya Transaksi Bank selama 1 tahun | E42: - | F42: 1998587 | G42: IDR | H42: 1 | N42: 1998587
D43: Biaya Interpretasi Log Data (D)
...

Sheet Laba rugi -2024
B3: PT. EXSPAN WIRELINE INDONESIA | G3: PT. EXSPAN WIRELINE INDONESIA
B4: LABA RUGI | TAHUN 2024 | G4: NERACA |TAHUN YANG BERAKHIR, 31 DESEMBER 2024
D6: PT. Exspan Wireline Indonesia | I6: PT. Exspan Wireline Indonesia
D7: (Rp) | I7: (Rp)
B8: PENDAPATAN | G8: AKTIVA
C9: PENDAPATAN LANGSUNG | D9: Rp | E9: =SUM('Revenue-Cost_2024'!L8:L20) | G9: AKTIVA LANCAR
C10: PENDAPATAN LAIN LAIN | D10: Rp | E10: =SUM('Revenue-Cost_2024'!L21:L21) | H10: KAS DAN SETARA KAS TAHUN SEBELUMNYA | I10: Rp | J10: 0
H11: KAS DAN SETARA KAS TAHUN LAPORAN | I11: Rp | J11: =E50-'Business Summary'!E13
B12: TOTAL PENDAPATAN | D12: Rp | E12: =SUM(E9:E11) | H12: PIUTANG USAHA | I12: Rp | J12: 0
H13: PAJAK BAYAR DI MUKA (pph23) | I13: Rp | J13: 0
B14: BEBAN LANGSUNG | H14: BIAYA BAYAR DI MUKA | I14: Rp | J14: 0
C15: BIAYA RESEARCH (R&D) | D15: Rp | E15: ='Revenue-Cost_2024'!I639 | H15: PIUTANG LAIN LAIN | I15: Rp | J15: 0
C16: BIAYA SEWA PERALATAN | D16: Rp | E16: ='Revenue-Cost_2024'!J639 | H16: TOTAL AKTIVA LANCAR | I16: Rp | J16: =SUM(J10:J15)
C17: BIAYA INTERPRETASI LOG DATA | D17: Rp | E17: ='Revenue-Cost_2024'!K639
C18: BIAYA OPERASI | D18: Rp | E18: ='Revenue-Cost_2024'!L639 | G18: ACTIVA TETAP
B19: TOTAL BIAYA LANGSUNG | D19: Rp | E19: =SUM(E15:E18)
H20: INVENTARIS KANTOR | I20: Rp | J20: 0
B21: BEBAN TIDAK LANGSUNG
D22: Rp | E22: 0 | H22: TOTAL AKTIVA TETAP | I22: Rp | J22: =J20
B23: TOTAL BIAYA TIDAK LANGSUNG | D23: Rp | E23: =SUM(E22:E22)
G24: ACTIVA LAIN LAIN | J24: 0
B25: BIAYA ADMINISTRASI DAN UMUM | J25: 0
C26: DIOFAVIAN | D26: Rp | E26: ='Revenue-Cost_2024'!M639 | H26: TOTAL AKTIVA LAIN LAIN | I26: Rp | J26: =SUM(J25:J25)
C27: ADMINISTRASI | D27: Rp | E27: ='Revenue-Cost_2024'!N639
C28: PEMBELIAN BARANG | D28: Rp | E28: ='Revenue-Cost_2024'!O639 | G28: TOTAL AKTIVA | I28: Rp | J28: =J26+J22+J16
C29: SEWA KANTOR | D29: Rp | E29: ='Revenue-Cost_2024'!P639
C30: KESEHATAN | D30: Rp | E30: ='Revenue-Cost_2024'!Q639 | G30: HUTANG DAN MODAL
C31: BISNIS DEV | D31: Rp | E31: ='Revenue-Cost_2024'!R639
C32: ASDASD | D32: Rp | E32: ='Revenue-Cost_2024'!S639 | G32: HUTANG LANCAR
C33: MAKANAN JEPANG | D33: Rp | E33: ='Revenue-Cost_2024'!T639 | H33: HUTANG USAHA | I33: Rp | J33: 0
C34: AAAAA | D34: Rp | E34: ='Revenue-Cost_2024'!U639 | H34: HUTANG GAJI | I34: Rp | J34: 0
C35: BBBBB | D35: Rp | E35: ='Revenue-Cost_2024'!V639 | H35: HUTANG PEMEGANG SAHAM | I35: Rp | J35: 0
C36: ASDSAD | D36: Rp | E36: ='Revenue-Cost_2024'!W639 | H36: BIAYA YANG MASIH HARUS DI BAYAR | I36: Rp | J36: 0
C37: DFGDFGDFGD | D37: Rp | E37: ='Revenue-Cost_2024'!X639
C38: 12312 | D38: Rp | E38: ='Revenue-Cost_2024'!Y639 | H38: TOTAL HUTANG LANCAR | J38: =SUM(J33:J36)
B39: TOTAL BIAYA ADMINISTRASI DAN UMUM | D39: Rp | E39: =SUM(E26:E38)
G40: MODAL
B41: TOTAL BIAYA | D41: Rp | E41: =E19+E23+E39 | H41: MODAL SAHAM | I41: Rp | J41: 0
H42: LABA DI TAHAN | I42: Rp | J42: 0
B43: PENDAPATAN/BEBAN LAIN LAIN | H43: TOTAL LABA (RUGI) DITAHAN | I43: Rp | J43: =J28-J38-J41-J42
...

Sheet Business Summary
B3: PT. EXSPAN WIRELINE INDONESIA
B4: BUSINESS SUMMARY | TAHUN 2024
B6: # | C6: Items | D6: Amount
B7: 1 | C7: Revenue | D7: Rp | E7: =SUM('Revenue-Cost_2024'!L8:L21)
B8: 2 | C8: Revenue Diterima (Setelah Pajak) | D8: Rp | E8: =E7-SUM('Revenue-Cost_2024'!N8:N21)
B9: 3 | C9: Biaya | D9: Rp | E9: =SUM('Revenue-Cost_2024'!I639:Y639)
B10: 4 | C10: Profit SebelumTax | D10: Rp | E10: =E7-E9
B11: 5 | C11: PPh Badan (22%*50%) | D11: Rp | E11: =E10*22%*50%
B12: 6 | C12: PPh 23 Dipotong oleh client | D12: Rp | E12: =SUM('Revenue-Cost_2024'!N8:N21)
B13: 7 | C13: Kekurangan Bayar PPh Badan | D13: Rp | E13: =E11-E12
B14: 8 | C14: Profit After Tax | D14: Rp | E14: =E10-E13
B15: 9 | C15: Deviden Dibagi | D15: Rp | E15: =E14-E16
B16: 10 | C16: Profit Ditahan | D16: Rp | E16: 33763737
B18: DEVIDEN
B19: # | C19: Nama Lengkap | E19: Amount | G19: Pajak
B20: 1 | C20: Anevril Chairulsyah | D20: Rp | E20: =IF(C20="","",ROUND($E$15/COUNTA($C$20:$C$21), 0)) | G20: Pajak 10%
B21: 2 | C21: Alan Muhadjir | D21: Rp | E21: =IF(C21="","",ROUND($E$15/COUNTA($C$20:$C$21), 0)) | G21: Pajak 10%
