Workbook

Sheet Revenue-Cost_2027
B1: Daily Report - Balance Calculation Operation Cost
B2: Project | C2: : | D2: REVENUE vs OPERATION COST Tahun 2027
B3: Date | C3: : | D3: Januari - Desember 2027
B5: REVENUE & TAX
B6: Invoice Date | C6: # | D6: Detail/Description | F6: INVOICE VALUE | G6: Currency | H6: Currency Exchange | I6: INVOICE Number | J6: Client | K6: Receive Date | L6: AMOUNT RECEIVED | M6: PPn | N6: PPH (Pasal 23) | O6: Biaya transfer | P6: Remark
D7: Belum ada data pendapatan
B8: REVENUE (IDR) | E8: =SUM(E7:E7) | K8: =SUM(K7:K7) | L8: =SUM(L7:L7) | M8: =SUM(M7:M7) | N8: =SUM(N7:N7) | P8: Pemungut
Q9: inc.PPN11%
P10: Pemungut
P11: Pemungut
P12: Pemungut
P13: Pemungut
Q14: inc.PPN11%
P15: Pemungut
Q16: inc.PPN11%
P17: Pemungut
P18: Pemungut
P19: Pemungut
P20: Pemungut
F22: 0 | N22: 0
B24: PAJAK PENGELUARAN
B25: Date | C25: # | D25: Detail/Description | F25: Transaction Value | G25: Currency | H25: Currency Exchange | I25: PPN | K25: PPh (pasal 21) | M25: PPh (pasal 23) | O25: PPh (pasal 26)
I26: Transaction | J26: PPN | K26: Transaction | L26: PPh - 21 | M26: Transaction | N26: PPh - 23 | O26: Transaction | P26: PPh - 26
C27: 1 | D27: Belum ada data pajak | G27: IDR | H27: 1
B37: PENERIMAAN NEGARA (TAX) (IDR) | I37: PPN | J37: 0 | K37: PPh | L37: 0 | M37: PPh | N37: 0 | O37: PPh | P37: 0 | Q37: -
B39: PENGELUARAN
B40: Date | C40: # | D40: Activity | E40: Source | F40: Jumlah | G40: Currency | H40: urrency Exchange | I40: Biaya Operasi | J40: Biaya Research (R&D) | K40: Biaya Sewa Peralatan | L40: Biaya Interpretasi Log Data | M40: Administrasi | N40: Pembelian Barang | O40: Sewa Kantor | P40: Kesehatan | Q40: Bisnis Dev | R40: asdasd | S40: makanan jepang | T40: aaaaa | U40: bbbbb | V40: asdsad | W40: dfgdfgdfgd | X40: 12312
D41: OPERATION COST AND OFFICE - Expenses Report
E42: TOTAL | F42: =SUM(F41:F41) | G42: IDR | H42: 1 | I42: =SUM(I41:I41) | J42: =SUM(J41:J41) | K42: =SUM(K41:K41) | L42: =SUM(L41:L41) | M42: =SUM(M41:M41) | N42: =SUM(N41:N41) | O42: =SUM(O41:O41) | P42: =SUM(P41:P41) | ... X42: =SUM(X41:X41)
B43: 45302 | C43: 3 | D43: ALFA Service JRK-254 Pertamina Zona#4 - Rental Tool | E43: BCA | F43: 29640916 | G43: IDR | H43: 1 | K43: =$F43*$H43
B44: 45304 | C44: 4 | D44: Sales cost 4 Well Integrity Pertamina Z.4 | E44: BRI | F44: 77672400 | G44: IDR | H44: 1 | I44: =$F44*$H44
B45: 45323 | C45: 5 | D45: Gaji Januari 2024 _Yufitri | E45: BCA | F45: 2500000 | G45: IDR | H45: 1 | I45: =F45
B46: 45356 | C46: 6 | D46: Gaji Februari 2024 + raple gaji Januari 2024_Yufitri | E46: BCA | F46: 3500000 | G46: IDR | H46: 1 | I46: 3500000
B47: 45364 | C47: 7 | D47: Ralika Jaya Utama | Permbuatan alat Downhole Wireless Telemetry | E47: BCA | F47: 100000000 | G47: IDR | H47: 1 | J47: =$F47*$H47
B48: 45379 | C48: 8 | D48: Gaji Maret 2024_Yufitri | E48: BCA | F48: 3000000 | G48: IDR | H48: 1 | I48: 3000000
B49: 45388 | C49: 9 | D49: THR 2024_Yufitri | E49: BCA | F49: 3000000 | G49: IDR | H49: 1 | I49: 3000000
B50: 45413 | C50: 10 | D50: Data proccesing MTD 4 well, project Tomori-Alan | E50: BCA | F50: 122625000 | G50: IDR | H50: 1 | L50: 122625000
B51: 45416 | C51: 11 | D51: Gaji April_Yufitri | E51: BCA | F51: 3000000 | G51: IDR | H51: 1 | I51: 3000000
B52: 45418 | C52: 12 | D52: Ralika Jaya Utama | Permbuatan alat Downhole Wireless Telemetry | E52: BRI | F52: 100000000 | G52: IDR | H52: 1 | J52: =$F52*$H52
B53: 45422 | C53: 13 | D53: Aro Energy | Moving slickline dari Duri (Toni Supriadi) ke Sungai lilin | E53: BCA | F53: 18000000 | G53: IDR | H53: 1 | I53: =$F53*$H53
...

Sheet Laba rugi -2027
B3: PT. EXSPAN WIRELINE INDONESIA | G3: PT. EXSPAN WIRELINE INDONESIA
B4: LABA RUGI | TAHUN 2027 | G4: NERACA | TAHUN YANG BERAKHIR, 31 DESEMBER 2027 | K4: CATATAN KEAMANAN
K5: Kolom ini aman dari overwrite sistem.
D6: PT. Exspan Wireline Indonesia | I6: PT. Exspan Wireline Indonesia | K6: Diverifikasi pada: 2026-03-30 17:38
D7: (Rp) | I7: (Rp)
B8: PENDAPATAN | G8: AKTIVA
C9: PENDAPATAN LANGSUNG | D9: Rp | E9: =SUM('Revenue-Cost_2027'!F8:F20) | G9: AKTIVA LANCAR
C10: PENDAPATAN LAIN LAIN | D10: Rp | E10: =SUM('Revenue-Cost_2027'!F21) | H10: KAS DAN SETARA KAS TAHUN SEBELUMNYA | I10: Rp | J10: 0
H11: KAS DAN SETARA KAS TAHUN LAPORAN | I11: Rp | J11: =E46-'Business Summary'!E13
B12: TOTALPENDAPATAN | D12: Rp | E12: =SUM(E9:E11) | H12: PIUTANG USAHA | I12: Rp | J12: 0
H13: PAJAK BAYAR DI MUKA (pph23) | I13: Rp | J13: 0
B14: BEBAN LANGSUNG | H14: BIAYA BAYAR DI MUKA | I14: Rp | J14: 0
C15: Biaya Operasi | D15: Rp | E15: ='Revenue-Cost_2027'!I750 | H15: PIUTANG LAIN LAIN | I15: Rp | J15: 0
C16: Biaya research (R & D) | D16: Rp | E16: ='Revenue-Cost_2027'!J750 | H16: TOTAL AKTIVA LANCAR | I16: Rp | J16: =SUM(J10:J15)
C17: BIAYA SEWA PERALATAN | D17: Rp | E17: ='Revenue-Cost_2027'!K750
C18: BIAYA Data Processing | D18: Rp | E18: ='Revenue-Cost_2027'!L750 | G18: ACTIVA TETAP
H20: INVENTARIS KANTOR | I20: Rp | J20: 0
B21: TOTAL BIAYA LANGSUNG | D21: Rp | E21: =SUM(E15:E20)
H22: TOTAL AKTIVA TETAP | I22: Rp | J22: =J20
B23: BEBAN TIDAK LANGSUNG | E23: ='Revenue-Cost_2027'!Q750
G24: ACTIVA LAIN LAIN | J24: 0
D25: Rp | J25: 0
H26: TOTAL AKTIVA LAIN LAIN | I26: Rp | J26: =SUM(J25:J25)
B27: TOTAL BIAYA TIDAK LANGSUNG | D27: Rp | E27: =SUM(E22:E26)
G28: TOTAL AKTIVA | I28: Rp | J28: =J26+J22+J16
B29: BIAYA ADMINISTRASI DAN UMUM
C30: BIAYA ADMINISTRASI | D30: Rp | E30: ='Revenue-Cost_2027'!M750 | G30: HUTANG DAN MODAL
C31: BIAYA PEMBELIAN Barang | D31: Rp | E31: ='Revenue-Cost_2027'!N750
C32: BIAYA SEWA KANTOR | D32: Rp | E32: ='Revenue-Cost_2027'!O750 | G32: HUTANG LANCAR
C33: BIAYA KESEHATAN | D33: Rp | E33: ='Revenue-Cost_2027'!P750 | H33: HUTANG USAHA | I33: Rp | J33: 0
H34: HUTANG GAJI | I34: Rp | J34: 0
B35: TOTAL BIAYA ADMINISTRASI DAN UMUM | D35: Rp | E35: =SUM(E30:E34) | H35: HUTANG PEMEGANG SAHAM | I35: Rp | J35: 0
H36: BIAYA YANG MASIH HARUS DI BAYAR | I36: Rp | J36: 0
B37: TOTAL BIAYA | D37: Rp | E37: =E35+E21+E27
H38: TOTAL HUTANG LANCAR | J38: =SUM(J33:J36)
B39: PENDAPATAN/BEBAN LAIN LAIN | D39: Rp
C40: PENDAPATAN LAINNYA | D40: Rp | E40: 0 | G40: MODAL
H41: MODAL SAHAM | I41: Rp | J41: 0
B42: LABA RUGI SEBELUM PAJAK | D42: Rp | E42: =E12-E37 | H42: LABA DI TAHAN | I42: Rp | J42: 0
H43: TOTAL LABA (RUGI) DITAHAN | I43: Rp | J43: =J28-J38-J41-J42
...

Sheet Business Summary
B3: PT. EXSPAN WIRELINE INDONESIA
B4: BUSINESS SUMMARY | TAHUN 2027
B6: # | C6: Items | D6: Amount
B7: 1 | C7: Revenue | D7: Rp | E7: ='Revenue-Cost_2027'!F22
B8: 2 | C8: Revenue Diterima (Setelah Pajak) | D8: Rp | E8: =E7-'Revenue-Cost_2027'!N22
B9: 3 | C9: Biaya | D9: Rp | E9: =SUM('Revenue-Cost_2027'!I750:Q750)
B10: 4 | C10: Profit SebelumTax | D10: Rp | E10: =E7-E9
B11: 5 | C11: PPh Badan (22%*50%) | D11: Rp | E11: =E10*22%*50%
B12: 6 | C12: PPh 23 Dipotong oleh client | D12: Rp | E12: ='Revenue-Cost_2027'!N22
B13: 7 | C13: Kekurangan Bayar PPh Badan | D13: Rp | E13: =E11-E12
B14: 8 | C14: Profit After Tax | D14: Rp | E14: =E10-E13
B15: 9 | C15: Deviden Dibagi | D15: Rp | E15: =E14-E16
B16: 10 | C16: Profit Ditahan | D16: Rp | E16: 0
B18: DEVIDEN
B19: # | C19: Nama Lengkap | E19: Amount | G19: Pajak
